Workbook

Sheet 00_README_Dashboard
A1: HPL AI Dispatching & Routing Engine - Simulated Data for Clustering & VRPTW
A3: Item | B3: Content | C3: Note
A4: Workbook | B4: HPL AI Dispatching & Routing Engine - Simulated Dataset for Clustering & VRPTW
A5: Purpose | B5: Bộ dữ liệu mô phỏng cho hàng phân phối, lập kế hoạch cuối ngày cho ngày hôm sau, chưa kích hoạt dynamic re-routing
A6: Scope | B6: 40 xe nội bộ, 3 kịch bản năng lực: thừa, đủ, thiếu; dữ liệu order có pickup/drop, time window, tải trọng, dung tích, cước, ràng buộc xe và rủi ro
A7: Algorithm-ready | B7: Sử dụng được cho phân cụm trước và VRPTW/PDPTW sau: tọa độ, time window dạng text và minute, demand pickup/delivery, service time, vehicle compatibility, revenue/penalty
A8: Key Logic | B8: Bám theo flow: Order Management → Validation → Clustering → VRPTW → Dispatch Board → Control Tower; tập trung pre-day planning
A9: Scenario S1 | B9: Năng lực công ty còn thừa so với order; giữ xe dự phòng và tối ưu chi phí/km rỗng
A10: Scenario S2 | B10: Năng lực công ty đáp ứng đủ; ưu tiên khóa kế hoạch và đảm bảo SLA
A11: Scenario S3 | B11: Năng lực công ty thiếu; kích hoạt thuê ngoài/chuyển tải/đàm phán khung giờ
A12: Scenario Capacity Summary
A13: Scenario_ID | B13: Case | C13: Orders | D13: Internal_Vehicles_Available | E13: Estimated_Route/Vehicle_Need | F13: Capacity_Gap | G13: Planning_Meaning | H13: Proposed_Operational_Response | I13: Algorithm_Settings | J13: Presentation_Note
A14: S1 | B14: Năng lực công ty còn thừa so với order khách hàng | C14: 30 | D14: 40 | E14: 28 | F14: 12 | G14: Có xe dự phòng, không cần thuê ngoài | H14: Ưu tiên phương án giảm km, giảm chạy rỗng, giữ 3-5 xe dự phòng cho phát sinh; chọn xe nhỏ cho nội đô và xe 5T/8T cho tuyến dài | I14: Balanced Mode + Empty-run Reduction | J14: Dùng để chứng minh hệ thống không chỉ tìm đường mà còn tối ưu năng lực dư
A15: S2 | B15: Năng lực công ty đáp ứng đủ so với order khách hàng | C15: 44 | D15: 40 | E15: 40 | F15: 0 | G15: Không còn nhiều xe dự phòng, cần khóa kế hoạch chặt | H15: Ưu tiên SLA và feasibility; giữ 1 danh sách xe backup/3PL standby nhưng chưa kích hoạt; dispatcher cần duyệt sớm và gửi tài xế trước 19:00 | I15: On-time Priority + Manual-assisted Mode | J15: Phù hợp case lập kế hoạch ngày hôm sau khi order vừa khớp năng lực
A16: S3 | B16: Năng lực công ty thiếu so với order khách hàng | C16: 60 | D16: 40 | E16: 52 | F16: -12 | G16: Thiếu xe nội bộ, phải thuê ngoài/chuyển tải/đàm phán giờ | H16: Kích hoạt 3PL/thuê ngoài cho tuyến dài và cụm low-margin; tách đơn quá tải nội đô; xin khách nới time window với đơn ưu tiên C; ưu tiên đơn SLA A và tuyến có lợi nhuận tốt | I16: Profit Maximization + On-time Priority + Split/Transshipment Enabled | J16: Dùng để trình bày năng lực xử lý thiếu xe và trade-off lead time/profit
A18: Quick Formula Checks
A19: Metric | B19: S1 | C19: S2 | D19: S3
A20: Orders count | B20: =COUNTA(S1_Thua_NangLuc!$C$2:$C$31) | C20: =COUNTA(S2_DapUng_Du!$C$2:$C$45) | D20: =COUNTA(S3_Thieu_NangLuc!$C$2:$C$61) | F20: Scenario check | G20: Meaning | H20: Action priority | I20: Use in deck
A21: Orders Ready | B21: =COUNTIF(S1_Thua_NangLuc!$BF$2:$BF$31,"Ready") | C21: =COUNTIF(S2_DapUng_Du!$BF$2:$BF$45,"Ready") | D21: =COUNTIF(S3_Thieu_NangLuc!$BF$2:$BF$61,"Ready") | F21: S1 | G21: Capacity surplus | H21: Cost/empty-run optimization | I21: Shows reserve capacity
A22: Orders Review | B22: =COUNTIF(S1_Thua_NangLuc!$BF$2:$BF$31,"Review") | C22: =COUNTIF(S2_DapUng_Du!$BF$2:$BF$45,"Review") | D22: =COUNTIF(S3_Thieu_NangLuc!$BF$2:$BF$61,"Review") | F22: S2 | G22: Capacity exact | H22: SLA lock + backup list | I22: Shows tight plan
A23: Total Revenue | B23: =SUM(S1_Thua_NangLuc!$AP$2:$AP$31) | C23: =SUM(S2_DapUng_Du!$AP$2:$AP$45) | D23: =SUM(S3_Thieu_NangLuc!$AP$2:$AP$61) | F23: S3 | G23: Capacity shortage | H23: 3PL/transshipment/reschedule | I23: Shows decision support
A24: Average Distance km | B24: =AVERAGE(S1_Thua_NangLuc!$W$2:$W$31) | C24: =AVERAGE(S2_DapUng_Du!$W$2:$W$45) | D24: =AVERAGE(S3_Thieu_NangLuc!$W$2:$W$61) | F24: All | G24: Pre-day planning only | H24: Dynamic event fields excluded from solver run | I24: Use nodes sheet for OR-Tools/VRPTW

Sheet 01_Data_Dictionary
A1: Sheet | B1: Field | C1: Definition / Use in Algorithm
A2: S1/S2/S3 Orders | B2: Scenario_ID | C2: Trường đơn hàng dùng cho validation, phân cụm và VRPTW
A3: S1/S2/S3 Orders | B3: Planning_Date | C3: Trường đơn hàng dùng cho validation, phân cụm và VRPTW
A4: S1/S2/S3 Orders | B4: Order_ID | C4: Trường đơn hàng dùng cho validation, phân cụm và VRPTW
A5: S1/S2/S3 Orders | B5: Customer_Group | C5: Trường đơn hàng dùng cho validation, phân cụm và VRPTW
A6: S1/S2/S3 Orders | B6: Customer_Name | C6: Trường đơn hàng dùng cho validation, phân cụm và VRPTW
A7: S1/S2/S3 Orders | B7: Channel | C7: Trường đơn hàng dùng cho validation, phân cụm và VRPTW
A8: S1/S2/S3 Orders | B8: SKU_Code | C8: Trường đơn hàng dùng cho validation, phân cụm và VRPTW
A9: S1/S2/S3 Orders | B9: Product_Group | C9: Trường đơn hàng dùng cho validation, phân cụm và VRPTW
A10: S1/S2/S3 Orders | B10: Pickup_ID | C10: Trường đơn hàng dùng cho validation, phân cụm và VRPTW
A11: S1/S2/S3 Orders | B11: Pickup_Name | C11: Trường đơn hàng dùng cho validation, phân cụm và VRPTW
A12: S1/S2/S3 Orders | B12: Pickup_Province | C12: Trường đơn hàng dùng cho validation, phân cụm và VRPTW
... A120: Algorithm_Nodes | B120: Notes | C120: Bảng node chuẩn hóa cho PDPTW/VRPTW: mỗi order có 1 pickup node và 1 delivery node

Sheet 02_Depots_Zones
A1: Location_ID | B1: Location_Name | C1: Type | D1: Province | E1: District | F1: Latitude | G1: Longitude | H1: Allowed_Vehicle_Types | I1: Operating_Start | J1: Operating_End | K1: Notes
A2: PK_HPL_LB | B2: HPL Depot Long Biên - 20 Thạch Bàn | C2: Depot | D2: Hà Nội | E2: Long Biên | F2: 21.026155 | G2: 105.91418 | H2: 5 tạ;1.25T;5T;8T;3 chân;4 chân | I2: 06:00 | J2: 20:00 | K2: Có thể làm điểm xuất phát/kết thúc cho tuyến
A3: PK_LINFOX_VSIP | B3: Kho Linfox KCN VSIP Bắc Ninh | C3: Customer Warehouse | D3: Bắc Ninh | E3: Từ Sơn | F3: 21.082707 | G3: 105.99795 | H3: 5 tạ;1.25T;5T;8T;3 chân;4 chân | I3: 06:00 | J3: 20:00 | K3: Có thể làm điểm xuất phát/kết thúc cho tuyến
A4: PK_HY_MYHAO | B4: Kho/Nhà máy khách hàng Mỹ Hào | C4: Customer Factory | D4: Hưng Yên | E4: Mỹ Hào | F4: 20.9329 | G4: 106.065 | H4: 5 tạ;1.25T;5T;8T;3 chân;4 chân | I4: 06:00 | J4: 20:00 | K4: Có thể làm điểm xuất phát/kết thúc cho tuyến
A5: PK_HP_DINHVU | B5: Kho Hải Phòng - Đình Vũ | C5: Port/Depot | D5: Hải Phòng | E5: Hải An | F5: 20.8425 | G5: 106.77 | H5: 5 tạ;1.25T;5T;8T;3 chân;4 chân | I5: 06:00 | J5: 20:00 | K5: Có thể làm điểm xuất phát/kết thúc cho tuyến
A6: PK_TH_QX | B6: Kho DC Thanh Hóa - Quảng Xương | C6: DC | D6: Thanh Hóa | E6: Quảng Xương | F6: 19.731 | G6: 105.815 | H6: 5 tạ;1.25T;5T;8T;3 chân;4 chân | I6: 06:00 | J6: 20:00 | K6: Có thể làm điểm xuất phát/kết thúc cho tuyến
A7: PK_NA_BACVINH | B7: Kho DC Vinh - KCN Bắc Vinh | C7: DC | D7: Nghệ An | E7: Vinh | F7: 18.733 | G7: 105.681 | H7: 5 tạ;1.25T;5T;8T;3 chân;4 chân | I7: 06:00 | J7: 20:00 | K7: Có thể làm điểm xuất phát/kết thúc cho tuyến
A9: Zone/Rules below
A10: Zone_ID | B10: Zone_Name | C10: Province/Coverage | D10: Rule_Type | E10: Vehicle_Limit | F10: Time_Window/Restriction | G10: Default_Service_Min | H10: Empty_Run_Rule | I10: Notes
A11: Z_HN_INNER | B11: Nội thành Hà Nội | C11: Hà Nội | D11: Road/Vehicle | E11: <=1.25T | F11: Cấm xe >1.25T giờ cao điểm 06:00-09:00 và 16:30-19:30 | G11: 25 | H11: <100km có thể chấp nhận rỗng | I11: Ưu tiên xe nhỏ, nhiều điểm, kiểm tra đường hẹp/dây điện thấp
A12: Z_HN_OUTER | B12: Ngoại thành Hà Nội | C12: Hoài Đức, Hà Đông, Long Biên | D12: Operational | E12: <=5T | F12: Tùy tuyến/kho | G12: 30 | H12: <100km có thể chấp nhận rỗng | I12: Có thể ghép đơn cùng trục
A13: Z_DB | B13: Đông Bắc | C13: Bắc Ninh, Hải Phòng, Quảng Ninh, Hải Dương | D13: Corridor | E13: <=8T/3 chân tùy điểm | F13: Theo khung giờ nhập kho | G13: 35 | H13: >100km cần tìm chuyến về | I13: Ưu tiên corridor matching và return load
A14: Z_TB | B14: Tây Bắc | C14: Thái Nguyên, Phú Thọ, Vĩnh Phúc | D14: Corridor | E14: <=8T | F14: Theo khách hàng | G14: 35 | H14: >100km cần tìm chuyến về | I14: Cần tránh nhảy trục Đông Bắc/Tây Bắc
A15: Z_BTB | B15: Bắc Trung Bộ | C15: Ninh Bình, Thanh Hóa, Nghệ An | D15: Corridor | E15: <=8T/3 chân | F15: Theo khách hàng | G15: 45 | H15: >100km bắt buộc cố gắng xin hàng kéo về | I15: Tuyến dài, cần kiểm tra backhaul

Sheet 03_Cost_Constraints
A1: Parameter | B1: Value | C1: Unit | D1: Business Meaning / Source in user-provided logic
A2: Planning_Date | B2: 2026-06-05 | C2: date | D2: Kế hoạch cuối ngày cho ngày hôm sau
A3: Diesel_Price | B3: 30020 | C3: VND/litre | D3: Giá dầu giả lập dùng cho tính chi phí nhiên liệu
A4: Default_Avg_Speed | B4: 50 | C4: km/h | D4: Dùng để tính Direct_Drive_Min nếu chưa có speed riêng
A5: Inner_City_Avg_Speed | B5: 35 | C5: km/h | D5: Nội thành Hà Nội, nhiều điểm và cấm tải
A6: Allowed_KM_Error | B6: 0.05 | C6: % | D6: Sai số km GPS/Vietmap/Bình Anh/Maxi khoảng 3-5%
A7: Empty_Run_Threshold | B7: 100 | C7: km | D7: <100km có thể chạy rỗng; >100km cần tìm chuyến quay đầu
A8: Target_Profit_Margin | B8: 0.1 | C8: % | D8: Mục tiêu tối thiểu theo meeting: lợi nhuận khoảng 10%
A9: Target_Improved_Margin | B9: 0.12 | C9: % | D9: Câu hỏi mục tiêu: cải thiện lên 12-15%
A10: Driver_Max_Continuous_Drive | B10: 4 | C10: hours | D10: Không lái liên tục quá 4h
A11: Driver_Max_Daily_Drive | B11: 10 | C11: hours | D11: Không quá 10h/ngày
A12: Clustering_Radius_Default | B12: 15 | C12: km | D12: Bán kính gom cụm demo
A13: Time_Compatibility_Window | B13: 120 | C13: minutes | D13: Khung giờ tương thích để gom cụm
A14: w1_GeoSim | B14: 0.25 | C14: weight | D14: Trọng số khoảng cách địa lý
... A20: w7_WaitingRisk | B20: 0.05 | C20: weight | D20: Điểm phạt rủi ro chờ

Sheet 04_Fleet_40
A1: Vehicle_ID | B1: Plate_No | C1: Vehicle_Type | D1: Vehicle_Class | E1: Max_Weight_kg | F1: Max_Volume_m3 | G1: Refrigerated | H1: Driver_ID | I1: Driver_Name | J1: Depot_ID | K1: Depot_Name | L1: Preferred_Corridor | M1: Shift_Start | N1: Shift_End | O1: Max_Driving_Hours_per_Day | P1: Max_Stops | Q1: Fuel_L_per_km | R1: Fuel_Cost_per_km | S1: EmptyRun_Cost_per_km | T1: Fixed_Cost_per_Day | U1: Driver_Cost_per_Trip | V1: Avg_Speed_kmph | W1: HN_Inner_Allowed | X1: Road_Access_Class | Y1: Status | Z1: Available_Date | AA1: Current_Lat | AB1: Current_Lon | AC1: GPS_Status | AD1: Notes
A2: V001 | B2: 30F-50137 | C2: 5 tạ | D2: Phân phối | E2: 500 | F2: 4 | G2: No | H2: DRV001 | I2: Tài xế 01 | J2: PK_LINFOX_VSIP | K2: Kho Linfox KCN VSIP Bắc Ninh | L2: Nội thành Hà Nội | M2: 06:00 | N2: 18:00 | O2: 10 | P2: 5 | Q2: 0.09 | R2: =Q2*'03_Cost_Constraints'!$B$3 | S2: =R2*1.15 | T2: 220000 | U2: 250000 | V2: 35 | W2: Yes | X2: Inner-city compatible | Y2: Available | Z2: 2026-06-05 | AA2: 21.082707 | AB2: 105.99795 | AC2: OK | AD2: Sẵn sàng lập kế hoạch ngày hôm sau
A3: V002 | B3: 31F-50274 | C3: 5 tạ | D3: Phân phối | E3: 500 | F3: 4 | G3: No | H3: DRV002 | I3: Tài xế 02 | J3: PK_HY_MYHAO | K3: Kho/Nhà máy khách hàng Mỹ Hào | L3: Nội thành Hà Nội | M3: 06:00 | N3: 18:00 | O3: 10 | P3: 5 | Q3: 0.09 | R3: =Q3*'03_Cost_Constraints'!$B$3 | S3: =R3*1.15 | T3: 220000 | U3: 250000 | V3: 35 | W3: Yes | X3: Inner-city compatible | Y3: Available | Z3: 2026-06-05 | AA3: 20.9329 | AB3: 106.065 | AC3: OK | AD3: Sẵn sàng lập kế hoạch ngày hôm sau
A4: V003 | B4: 34C-50411 | C4: 5 tạ | D4: Phân phối | E4: 500 | F4: 4 | G4: No | H4: DRV003 | I4: Tài xế 03 | J4: PK_HP_DINHVU | K4: Kho Hải Phòng - Đình Vũ | L4: Nội thành Hà Nội | M4: 06:00 | N4: 18:00 | O4: 10 | P4: 5 | Q4: 0.09 | R4: =Q4*'03_Cost_Constraints'!$B$3 | S4: =R4*1.15 | T4: 220000 | U4: 250000 | V4: 35 | W4: Yes | X4: Inner-city compatible | Y4: Available | Z4: 2026-06-05 | AA4: 20.8425 | AB4: 106.77 | AC4: OK | AD4: Sẵn sàng lập kế hoạch ngày hôm sau
A5: V004 | B5: 36C-50548 | C5: 5 tạ | D5: Phân phối | E5: 500 | F5: 4 | G5: No | H5: DRV004 | I5: Tài xế 04 | J5: PK_TH_QX | K5: Kho DC Thanh Hóa - Quảng Xương | L5: Nội thành Hà Nội | M5: 06:00 | N5: 18:00 | O5: 10 | P5: 5 | Q5: 0.09 | R5: =Q5*'03_Cost_Constraints'!$B$3 | S5: =R5*1.15 | T5: 220000 | U5: 250000 | V5: 35 | W5: Yes | X5: Inner-city compatible | Y5: Available | Z5: 2026-06-05 | AA5: 19.731 | AB5: 105.815 | AC5: OK | AD5: Sẵn sàng lập kế hoạch ngày hôm sau
A6: V005 | B6: 17C-50685 | C6: 5 tạ | D6: Phân phối | E6: 500 | F6: 4 | G6: No | H6: DRV005 | I6: Tài xế 05 | J6: PK_NA_BACVINH | K6: Kho DC Vinh - KCN Bắc Vinh | L6: Nội thành Hà Nội | M6: 06:00 | N6: 18:00 | O6: 10 | P6: 5 | Q6: 0.09 | R6: =Q6*'03_Cost_Constraints'!$B$3 | S6: =R6*1.15 | T6: 220000 | U6: 250000 | V6: 35 | W6: Yes | X6: Inner-city compatible | Y6: Available | Z6: 2026-06-05 | AA6: 18.733 | AB6: 105.681 | AC6: OK | AD6: Sẵn sàng lập kế hoạch ngày hôm sau
A7: V006 | B7: 29C-50822 | C7: 5 tạ | D7: Phân phối | E7: 500 | F7: 4 | G7: No | H7: DRV006 | I7: Tài xế 06 | J7: PK_HPL_LB | K7: HPL Depot Long Biên - 20 Thạch Bàn | L7: Nội thành Hà Nội | M7: 06:00 | N7: 18:00 | O7: 10 | P7: 5 | Q7: 0.09 | R7: =Q7*'03_Cost_Constraints'!$B$3 | S7: =R7*1.15 | T7: 220000 | U7: 250000 | V7: 35 | W7: Yes | X7: Inner-city compatible | Y7: Available | Z7: 2026-06-05 | AA7: 21.026155 | AB7: 105.91418 | AC7: OK | AD7: Sẵn sàng lập kế hoạch ngày hôm sau
A8: V007 | B8: 30F-50959 | C8: 1.25T | D8: Phân phối | E8: 1250 | F8: 10 | G8: No | H8: DRV007 | I8: Tài xế 07 | J8: PK_LINFOX_VSIP | K8: Kho Linfox KCN VSIP Bắc Ninh | L8: Nội thành Hà Nội | M8: 06:00 | N8: 18:00 | O8: 10 | P8: 8 | Q8: 0.12 | R8: =Q8*'03_Cost_Constraints'!$B$3 | S8: =R8*1.15 | T8: 300000 | U8: 300000 | V8: 35 | W8: Yes | X8: Inner-city compatible | Y8: Available | Z8: 2026-06-05 | AA8: 21.082707 | AB8: 105.99795 | AC8: OK | AD8: Sẵn sàng lập kế hoạch ngày hôm sau
A9: V008 | B9: 31F-51096 | C9: 1.25T | D9: Phân phối | E9: 1250 | F9: 10 | G9: No | H9: DRV008 | I9: Tài xế 08 | J9: PK_HY_MYHAO | K9: Kho/Nhà máy khách hàng Mỹ Hào | L9: Nội thành Hà Nội | M9: 06:00 | N9: 18:00 | O9: 10 | P9: 8 | Q9: 0.12 | R9: =Q9*'03_Cost_Constraints'!$B$3 | S9: =R9*1.15 | T9: 300000 | U9: 300000 | V9: 35 | W9: Yes | X9: Inner-city compatible | Y9: Available | Z9: 2026-06-05 | AA9: 20.9329 | AB9: 106.065 | AC9: OK | AD9: Sẵn sàng lập kế hoạch ngày hôm sau
A10: V009 | B10: 34C-51233 | C10: 1.25T | D10: Phân phối | E10: 1250 | F10: 10 | G10: No | H10: DRV009 | I10: Tài xế 09 | J10: PK_HP_DINHVU | K10: Kho Hải Phòng - Đình Vũ | L10: Nội thành Hà Nội | M10: 06:00 | N10: 18:00 | O10: 10 | P10: 8 | Q10: 0.12 | R10: =Q10*'03_Cost_Constraints'!$B$3 | S10: =R10*1.15 | T10: 300000 | U10: 300000 | V10: 35 | W10: Yes | X10: Inner-city compatible | Y10: Available | Z10: 2026-06-05 | AA10: 20.8425 | AB10: 106.77 | AC10: OK | AD10: Sẵn sàng lập kế hoạch ngày hôm sau
A11: V010 | B11: 36C-51370 | C11: 1.25T | D11: Phân phối | E11: 1250 | F11: 10 | G11: No | H11: DRV010 | I11: Tài xế 10 | J11: PK_TH_QX | K11: Kho DC Thanh Hóa - Quảng Xương | L11: Nội thành Hà Nội | M11: 06:00 | N11: 18:00 | O11: 10 | P11: 8 | Q11: 0.12 | R11: =Q11*'03_Cost_Constraints'!$B$3 | S11: =R11*1.15 | T11: 300000 | U11: 300000 | V11: 35 | W11: Yes | X11: Inner-city compatible | Y11: Available | Z11: 2026-06-05 | AA11: 19.731 | AB11: 105.815 | AC11: OK | AD11: Sẵn sàng lập kế hoạch ngày hôm sau
A12: V011 | B12: 17C-51507 | C12: 1.25T | D12: Phân phối | E12: 1250 | F12: 10 | G12: No | H12: DRV011 | I12: Tài xế 11 | J12: PK_NA_BACVINH | K12: Kho DC Vinh - KCN Bắc Vinh | L12: Nội thành Hà Nội | M12: 06:00 | N12: 18:00 | O12: 10 | P12: 8 | Q12: 0.12 | R12: =Q12*'03_Cost_Constraints'!$B$3 | S12: =R12*1.15 | T12: 300000 | U12: 300000 | V12: 35 | W12: Yes | X12: Inner-city compatible | Y12: Available | Z12: 2026-06-05 | AA12: 18.733 | AB12: 105.681 | AC12: OK | AD12: Sẵn sàng lập kế hoạch ngày hôm sau
A13: V012 | B13: 29C-51644 | C13: 1.25T | D13: Phân phối | E13: 1250 | F13: 10 | G13: No | H13: DRV012 | I13: Tài xế 12 | J13: PK_HPL_LB | K13: HPL Depot Long Biên - 20 Thạch Bàn | L13: Nội thành Hà Nội | M13: 06:00 | N13: 18:00 | O13: 10 | P13: 8 | Q13: 0.12 | R13: =Q13*'03_Cost_Constraints'!$B$3 | S13: =R13*1.15 | T13: 300000 | U13: 300000 | V13: 35 | W13: Yes | X13: Inner-city compatible | Y13: Available | Z13: 2026-06-05 | AA13: 21.026155 | AB13: 105.91418 | AC13: OK | AD13: Sẵn sàng lập kế hoạch ngày hôm sau
... A41: V040 | B41: 36C-55480 | C41: 4 chân | D41: Phân phối | E41: 18000 | F41: 90 | G41: No | H41: DRV040 | I41: Tài xế 40 | J41: PK_NA_BACVINH | K41: Kho DC Vinh - KCN Bắc Vinh | L41: Bắc Trung Bộ | M41: 06:00 | N41: 18:00 | O41: 10 | P41: 3 | Q41: 0.39 | R41: =Q41*'03_Cost_Constraints'!$B$3 | S41: =R41*1.15 | T41: 1100000 | U41: 650000 | V41: 50 | W41: No | X41: Main-road only | Y41: Available | Z41: 2026-06-05 | AA41: 18.733 | AB41: 105.681 | AC41: OK | AD41: Sẵn sàng lập kế hoạch ngày hôm sau

Sheet S1_Thua_NangLuc
A1: Scenario_ID | B1: Planning_Date | C1: Order_ID | D1: Customer_Group | E1: Customer_Name | F1: Channel | G1: SKU_Code | H1: Product_Group | I1: Pickup_ID | J1: Pickup_Name | K1: Pickup_Province | L1: Pickup_District | M1: Pickup_Lat | N1: Pickup_Lon | O1: Delivery_ID | P1: Delivery_Name | Q1: Delivery_Province | R1: Delivery_District | S1: Delivery_Lat | T1: Delivery_Lon | U1: Corridor | V1: Route_Axis | W1: Direct_Distance_km | X1: Weight_kg | Y1: Volume_m3 | Z1: Pallet_Qty | AA1: Min_Vehicle_Type | AB1: Max_Vehicle_Type_Allowed | AC1: Required_Refrigeration | AD1: Can_Consolidate | AE1: Dedicated_Vehicle | AF1: Inner_City_Restriction | AG1: Access_Note | AH1: Pickup_TW_Start | AI1: Pickup_TW_End | AJ1: Drop_TW_Start | AK1: Drop_TW_End | AL1: TW_Flex_Min | AM1: Pickup_Service_Min | AN1: Drop_Service_Min | AO1: Lead_Time_Min | AP1: Freight_Revenue_VND | AQ1: Extra_Stop_Fee_VND | AR1: Waiting_Fee_Chargeable_VND | AS1: Late_Penalty_VND_per_30m | AT1: Customer_Priority | AU1: Contract_Route_ID | AV1: Source_System | AW1: Seed_Cluster_ID | AX1: Suggested_Vehicle_Type | AY1: Suggested_Action | AZ1: Validation_Status | BA1: Risk_Flag | BB1: Total_Service_Min | BC1: Direct_Drive_Min | BD1: Load_Class_kg | BE1: LeadTime_Check | BF1: Algorithm_Ready_Flag | BG1: Notes
A2: S1 | B2: 2026-06-05 | C2: S1-ORD-001 | D2: Linfox | E2: VINMART Võ Thị Sáu | F2: ST | G2: PAT2 | H2: Bia lon 333 | I2: PK_HY_MYHAO | J2: Kho/Nhà máy khách hàng Mỹ Hào | K2: Hưng Yên | L2: Mỹ Hào | M2: 20.9329 | N2: 106.065 | O2: DL_HN_VOTHISAU | P2: VINMART Võ Thị Sáu | Q2: Hà Nội | R2: Hai Bà Trưng | S2: 21.00441 | T2: 105.85515 | U2: Nội thành Hà Nội | V2: Nội thành Hà Nội | W2: 41.3 | X2: 385 | Y2: 0.93 | Z2: 1 | AA2: 5 tạ | AB2: 1.25T | AC2: No | AD2: Yes | AE2: No | AF2: Yes | AG2: Giờ cấm tải, xe <=1.25T | AH2: 08:00 | AI2: 10:30 | AJ2: 10:55 | AK2: 12:25 | AL2: 45 | AM2: 25 | AN2: 20 | AO2: 265 | AP2: 670000 | AQ2: 0 | AR2: 0 | AS2: 150000 | AT2: A - SLA chặt | AU2: CR-NỘIT-02 | AV2: Manual nhập điều phối | AW2: S1-C01 | AX2: 5 tạ | AY2: Send to Clustering | AZ2: OK | BA2: Cấm tải/đường nhỏ - đã chọn xe nhỏ | BB2: =AM2+AN2 | BC2: =ROUND(W2/'03_Cost_Constraints'!$B$4*60,0) | BD2: =IF(X2<=500,"5 tạ",IF(X2<=1250,"1.25T",IF(X2<=5000,"5T",IF(X2<=8000,"8T",IF(X2<=15000,"3 chân","4 chân"))))) | BE2: =IF((BB2+BC2)<=AO2,"OK","Risk") | BF2: =IF(AND(AZ2="OK",BE2="OK"),"Ready","Review")
A3: S1 | B3: 2026-06-05 | C3: S1-ORD-002 | D3: Linfox | E3: VINMART Royal City | F3: MT | G3: PAT2 | H3: Bia lon 333 | I3: PK_HY_MYHAO | J3: Kho/Nhà máy khách hàng Mỹ Hào | K3: Hưng Yên | L3: Mỹ Hào | M3: 20.9329 | N3: 106.065 | O3: DL_HN_ROYAL | P3: VINMART Royal City | Q3: Hà Nội | R3: Thanh Xuân | S3: 21.003388 | T3: 105.81621 | U3: Nội thành Hà Nội | V3: Nội thành Hà Nội | W3: 42.8 | X3: 307 | Y3: 0.88 | Z3: 1 | AA3: 5 tạ | AB3: 1.25T | AC3: No | AD3: Yes | AE3: No | AF3: Yes | AG3: Hầm trung tâm thương mại | AH3: 08:30 | AI3: 10:00 | AJ3: 11:58 | AK3: 13:58 | AL3: 45 | AM3: 25 | AN3: 30 | AO3: 328 | AP3: 860000 | AQ3: 0 | AR3: 120000 | AS3: 80000 | AT3: B - Thường | AU3: CR-NỘIT-03 | AV3: Excel khách hàng | AW3: S1-C02 | AX3: 5 tạ | AY3: Send to Clustering | AZ3: OK | BA3: Cấm tải/đường nhỏ - đã chọn xe nhỏ | BB3: =AM3+AN3 | BC3: =ROUND(W3/'03_Cost_Constraints'!$B$4*60,0) | BD3: =IF(X3<=500,"5 tạ",IF(X3<=1250,"1.25T",IF(X3<=5000,"5T",IF(X3<=8000,"8T",IF(X3<=15000,"3 chân","4 chân"))))) | BE3: =IF((BB3+BC3)<=AO3,"OK","Risk") | BF3: =IF(AND(AZ3="OK",BE3="OK"),"Ready","Review")
A4: S1 | B4: 2026-06-05 | C4: S1-ORD-003 | D4: MM Mega Market | E4: VINMART Quế Võ | F4: ST | G4: MILK | H4: Sữa hộp carton | I4: PK_LINFOX_VSIP | J4: Kho Linfox KCN VSIP Bắc Ninh | K4: Bắc Ninh | L4: Từ Sơn | M4: 21.082707 | N4: 105.99795 | O4: DL_BN_QUEVO_01 | P4: VINMART Quế Võ | Q4: Bắc Ninh | R4: Quế Võ | S4: 21.170139 | T4: 106.1024 | U4: Đông Bắc | V4: Đông Bắc | W4: 25.1 | X4: 7751 | Y4: 16.16 | Z4: 13 | AA4: 8T | AB4: 8T | AC4: No | AD4: Yes | AE4: No | AF4: No | AG4: Đường rộng, xe 5T/8T vào được | AH4: 07:30 | AI4: 09:00 | AJ4: 10:03 | AK4: 12:03 | AL4: 30 | AM4: 40 | AN4: 35 | AO4: 273 | AP4: 1810000 | AQ4: 150000 | AR4: 0 | AS4: 80000 | AT4: C - Có thể thương lượng | AU4: CR-ĐÔNG-04 | AV4: Hệ thống khách hàng | AW4: S1-C03 | AX4: 8T | AY4: Send to Clustering | AZ4: OK | BA4: OK | BB4: =AM4+AN4 | BC4: =ROUND(W4/'03_Cost_Constraints'!$B$4*60,0) | BD4: =IF(X4<=500,"5 tạ",IF(X4<=1250,"1.25T",IF(X4<=5000,"5T",IF(X4<=8000,"8T",IF(X4<=15000,"3 chân","4 chân"))))) | BE4: =IF((BB4+BC4)<=AO4,"OK","Risk") | BF4: =IF(AND(AZ4="OK",BE4="OK"),"Ready","Review")
A5: S1 | B5: 2026-06-05 | C5: S1-ORD-004 | D5: Bách Hóa Xanh | E5: VINMART Bắc Từ Liêm | F5: ST | G5: LVCA | H5: Bia lon Lạc Việt | I5: PK_HY_MYHAO | J5: Kho/Nhà máy khách hàng Mỹ Hào | K5: Hưng Yên | L5: Mỹ Hào | M5: 20.9329 | N5: 106.065 | O5: DL_HN_BACTULIEM | P5: VINMART Bắc Từ Liêm | Q5: Hà Nội | R5: Bắc Từ Liêm | S5: 21.052701 | T5: 105.78073 | U5: Nội thành Hà Nội | V5: Nội thành Hà Nội | W5: 54.1 | X5: 226 | Y5: 0.6 | Z5: 1 | AA5: 5 tạ | AB5: 1.25T | AC5: No | AD5: Yes | AE5: No | AF5: Yes | AG5: Nội đô, khung giờ hạn chế xe tải | AH5: 07:00 | AI5: 09:00 | AJ5: 09:17 | AK5: 12:17 | AL5: 45 | AM5: 25 | AN5: 20 | AO5: 317 | AP5: 850000 | AQ5: 0 | AR5: 0 | AS5: 80000 | AT5: C - Có thể thương lượng | AU5: CR-NỘIT-05 | AV5: Zalo/Email plan 17:00 | AW5: S1-C04 | AX5: 5 tạ | AY5: Send to Clustering | AZ5: OK | BA5: Cấm tải/đường nhỏ - đã chọn xe nhỏ | BB5: =AM5+AN5 | BC5: =ROUND(W5/'03_Cost_Constraints'!$B$4*60,0) | BD5: =IF(X5<=500,"5 tạ",IF(X5<=1250,"1.25T",IF(X5<=5000,"5T",IF(X5<=8000,"8T",IF(X5<=15000,"3 chân","4 chân"))))) | BE5: =IF((BB5+BC5)<=AO5,"OK","Risk") | BF5: =IF(AND(AZ5="OK",BE5="OK"),"Ready","Review") | BG5: Kế hoạch ngày hôm sau; cần chốt trước 19:00 và gửi tài xế sau duyệt
A6: S1 | B6: 2026-06-05 | C6: S1-ORD-005 | D6: Bách Hóa Xanh | E6: VINMART Võ Thị Sáu | F6: ST | G6: CHCA | H6: Bia lon Saigon Chill | I6: PK_HPL_LB | J6: HPL Depot Long Biên - 20 Thạch Bàn | K6: Hà Nội | L6: Long Biên | M6: 21.026155 | N6: 105.91418 | O6: DL_HN_VOTHISAU | P6: VINMART Võ Thị Sáu | Q6: Hà Nội | R6: Hai Bà Trưng | S6: 21.00441 | T6: 105.85515 | U6: Nội thành Hà Nội | V6: Nội thành Hà Nội | W6: 15.8 | X6: 661 | Y6: 1.58 | Z6: 1 | AA6: 1.25T | AB6: 1.25T | AC6: No | AD6: Yes | AE6: No | AF6: Yes | AG6: Giờ cấm tải, xe <=1.25T | AH6: 07:00 | AI6: 09:30 | AJ6: 09:12 | AK6: 11:12 | AL6: 45 | AM6: 25 | AN6: 20 | AO6: 252 | AP6: 490000 | AQ6: 0 | AR6: 0 | AS6: 80000 | AT6: B - Thường | AU6: CR-NỘIT-01 | AV6: Manual nhập điều phối | AW6: S1-C05 | AX6: 1.25T | AY6: Send to Clustering | AZ6: OK | BA6: Cấm tải/đường nhỏ - đã chọn xe nhỏ | BB6: =AM6+AN6 | BC6: =ROUND(W6/'03_Cost_Constraints'!$B$4*60,0) | BD6: =IF(X6<=500,"5 tạ",IF(X6<=1250,"1.25T",IF(X6<=5000,"5T",IF(X6<=8000,"8T",IF(X6<=15000,"3 chân","4 chân"))))) | BE6: =IF((BB6+BC6)<=AO6,"OK","Risk") | BF6: =IF(AND(AZ6="OK",BE6="OK"),"Ready","Review")
A7: S1 | B7: 2026-06-05 | C7: S1-ORD-006 | D7: Masan | E7: Siêu thị Hải Dương | F7: ST | G7: POSM | H7: POSM trưng bày | I7: PK_HPL_LB | J7: HPL Depot Long Biên - 20 Thạch Bàn | K7: Hà Nội | L7: Long Biên | M7: 21.026155 | N7: 105.91418 | O7: DL_HD_SIEUTHI | P7: Siêu thị Hải Dương | Q7: Hải Phòng | R7: Hải Dương | S7: 20.937341 | T7: 106.31455 | U7: Đông Bắc | V7: Đông Bắc | W7: 62.1 | X7: 7814 | Y7: 172.96 | Z7: 144 | AA7: Container | AB7: 8T | AC7: No | AD7: Yes | AE7: No | AF7: No | AG7: Quốc lộ 5, xe 8T vào được | AH7: 07:00 | AI7: 09:30 | AJ7: 12:12 | AK7: 14:12 | AL7: 30 | AM7: 120 | AN7: 90 | AO7: 432 | AP7: 3320000 | AQ7: 150000 | AR7: 0 | AS7: 80000 | AT7: C - Có thể thương lượng | AU7: CR-ĐÔNG-02 | AV7: Excel khách hàng | AW7: S1-C06 | AX7: Split/Chuyển tải | AY7: Split Order/Chuyển tải hoặc xin xe nhỏ nhiều chuyến | AZ7: Review | BA7: Vehicle Mismatch | BB7: =AM7+AN7 | BC7: =ROUND(W7/'03_Cost_Constraints'!$B$4*60,0) | BD7: =IF(X7<=500,"5 tạ",IF(X7<=1250,"1.25T",IF(X7<=5000,"5T",IF(X7<=8000,"8T",IF(X7<=15000,"3 chân","4 chân"))))) | BE7: =IF((BB7+BC7)<=AO7,"OK","Risk") | BF7: =IF(AND(AZ7="OK",BE7="OK"),"Ready","Review")
A8: S1 | B8: 2026-06-05 | C8: S1-ORD-007 | D8: Masan | E8: Thái Dương | F8: Đại lý | G8: POSM | H8: POSM trưng bày | I8: PK_HY_MYHAO | J8: Kho/Nhà máy khách hàng Mỹ Hào | K8: Hưng Yên | L8: Mỹ Hào | M8: 20.9329 | N8: 106.065 | O8: DL_HN_THAIDUONG | P8: Thái Dương | Q8: Hà Nội | R8: Hà Nội | S8: 20.929215 | T8: 105.87 | U8: Nội thành Hà Nội | V8: Nội thành Hà Nội | W8: 31.3 | X8: 1470 | Y8: 33.65 | Z8: 28 | AA8: 8T | AB8: 1.25T | AC8: No | AD8: Yes | AE8: No | AF8: Yes | AG8: Đường nhỏ, ưu tiên xe <=1.25T | AH8: 07:00 | AI8: 09:00 | AJ8: 09:23 | AK8: 11:23 | AL8: 30 | AM8: 40 | AN8: 35 | AO8: 263 | AP8: 660000 | AQ8: 0 | AR8: 0 | AS8: 80000 | AT8: B - Thường | AU8: CR-NỘIT-03 | AV8: Hệ thống khách hàng | AW8: S1-C07 | AX8: Split/Chuyển tải | AY8: Split Order/Chuyển tải hoặc xin xe nhỏ nhiều chuyến | AZ8: Review | BA8: Vehicle Mismatch | BB8: =AM8+AN8 | BC8: =ROUND(W8/'03_Cost_Constraints'!$B$4*60,0) | BD8: =IF(X8<=500,"5 tạ",IF(X8<=1250,"1.25T",IF(X8<=5000,"5T",IF(X8<=8000,"8T",IF(X8<=15000,"3 chân","4 chân"))))) | BE8: =IF((BB8+BC8)<=AO8,"OK","Risk") | BF8: =IF(AND(AZ8="OK",BE8="OK"),"Ready","Review")
A9: S1 | B9: 2026-06-05 | C9: S1-ORD-008 | D9: Acecook | E9: VINMART Võ Thị Sáu | F9: ST | G9: POSM | H9: POSM trưng bày | I9: PK_LINFOX_VSIP | J9: Kho Linfox KCN VSIP Bắc Ninh | K9: Bắc Ninh | L9: Từ Sơn | M9: 21.082707 | N9: 105.99795 | O9: DL_HN_VOTHISAU | P9: VINMART Võ Thị Sáu | Q9: Hà Nội | R9: Hai Bà Trưng | S9: 21.00441 | T9: 105.85515 | U9: Nội thành Hà Nội | V9: Nội thành Hà Nội | W9: 31.9 | X9: 1371 | Y9: 32.73 | Z9: 27 | AA9: 8T | AB9: 1.25T | AC9: No | AD9: Yes | AE9: No | AF9: Yes | AG9: Giờ cấm tải, xe <=1.25T | AH9: 09:00 | AI9: 10:30 | AJ9: 12:24 | AK9: 14:24 | AL9: 45 | AM9: 40 | AN9: 35 | AO9: 324 | AP9: 650000 | AQ9: 0 | AR9: 0 | AS9: 80000 | AT9: C - Có thể thương lượng | AU9: CR-NỘIT-04 | AV9: Zalo/Email plan 17:00 | AW9: S1-C07 | AX9: Split/Chuyển tải | AY9: Split Order/Chuyển tải hoặc xin xe nhỏ nhiều chuyến | AZ9: Review | BA9: Vehicle Mismatch | BB9: =AM9+AN9 | BC9: =ROUND(W9/'03_Cost_Constraints'!$B$4*60,0) | BD9: =IF(X9<=500,"5 tạ",IF(X9<=1250,"1.25T",IF(X9<=5000,"5T",IF(X9<=8000,"8T",IF(X9<=15000,"3 chân","4 chân"))))) | BE9: =IF((BB9+BC9)<=AO9,"OK","Risk") | BF9: =IF(AND(AZ9="OK",BE9="OK"),"Ready","Review") | BG9: Kế hoạch ngày hôm sau; cần chốt trước 19:00 và gửi tài xế sau duyệt
A10: S1 | B10: 2026-06-05 | C10: S1-ORD-009 | D10: MM Mega Market | E10: VINMART Hoài Đức | F10: ST | G10: EXPL | H10: Bia lon Saigon Export | I10: PK_HPL_LB | J10: HPL Depot Long Biên - 20 Thạch Bàn | K10: Hà Nội | L10: Long Biên | M10: 21.026155 | N10: 105.91418 | O10: DL_HN_HOAIDUC | P10: VINMART Hoài Đức | Q10: Hà Nội | R10: Hoài Đức | S10: 21.005046 | T10: 105.72829 | U10: Tây Bắc | V10: Tây Bắc | W10: 28.9 | X10: 4822 | Y10: 12.04 | Z10: 10 | AA10: 5T | AB10: 5T | AC10: No | AD10: Yes | AE10: No | AF10: No | AG10: Ngoại thành, xe 5T vào được | AH10: 08:00 | AI10: 10:30 | AJ10: 09:38 | AK10: 12:38 | AL10: 30 | AM10: 40 | AN10: 35 | AO10: 278 | AP10: 1170000 | AQ10: 150000 | AR10: 0 | AS10: 80000 | AT10: C - Có thể thương lượng | AU10: CR-TÂYB-05 | AV10: Manual nhập điều phối | AW10: S1-C09 | AX10: 5T | AY10: Send to Clustering | AZ10: OK | BA10: OK | BB10: =AM10+AN10 | BC10: =ROUND(W10/'03_Cost_Constraints'!$B$4*60,0) | BD10: =IF(X10<=500,"5 tạ",IF(X10<=1250,"1.25T",IF(X10<=5000,"5T",IF(X10<=8000,"8T",IF(X10<=15000,"3 chân","4 chân"))))) | BE10: =IF((BB10+BC10)<=AO10,"OK","Risk") | BF10: =IF(AND(AZ10="OK",BE10="OK"),"Ready","Review")
A11: S1 | B11: 2026-06-05 | C11: S1-ORD-010 | D11: Acecook | E11: Thái Dương | F11: Đại lý | G11: SP33 | H11: Bia lon Saigon Special | I11: PK_LINFOX_VSIP | J11: Kho Linfox KCN VSIP Bắc Ninh | K11: Bắc Ninh | L11: Từ Sơn | M11: 21.082707 | N11: 105.99795 | O11: DL_HN_THAIDUONG | P11: Thái Dương | Q11: Hà Nội | R11: Hà Nội | S11: 20.929215 | T11: 105.87 | U11: Nội thành Hà Nội | V11: Nội thành Hà Nội | W11: 35.5 | X11: 909 | Y11: 1.5 | Z11: 1 | AA11: 1.25T | AB11: 1.25T | AC11: No | AD11: Yes | AE11: No | AF11: Yes | AG11: Đường nhỏ, ưu tiên xe <=1.25T | AH11: 07:00 | AI11: 08:30 | AJ11: 09:15 | AK11: 10:45 | AL11: 45 | AM11: 25 | AN11: 20 | AO11: 225 | AP11: 600000 | AQ11: 0 | AR11: 0 | AS11: 80000 | AT11: C - Có thể thương lượng | AU11: CR-NỘIT-01 | AV11: Excel khách hàng | AW11: S1-C10 | AX11: 1.25T | AY11: Send to Clustering | AZ11: OK | BA11: Cấm tải/đường nhỏ - đã chọn xe nhỏ | BB11: =AM11+AN11 | BC11: =ROUND(W11/'03_Cost_Constraints'!$B$4*60,0) | BD11: =IF(X11<=500,"5 tạ",IF(X11<=1250,"1.25T",IF(X11<=5000,"5T",IF(X11<=8000,"8T",IF(X11<=15000,"3 chân","4 chân"))))) | BE11: =IF((BB11+BC11)<=AO11,"OK","Risk") | BF11: =IF(AND(AZ11="OK",BE11="OK"),"Ready","Review")
A12: S1 | B12: 2026-06-05 | C12: S1-ORD-011 | D12: MM Mega Market | E12: VINMART Bắc Từ Liêm | F12: ST | G12: SP33 | H12: Bia lon Saigon Special | I12: PK_HPL_LB | J12: HPL Depot Long Biên - 20 Thạch Bàn | K12: Hà Nội | L12: Long Biên | M12: 21.026155 | N12: 105.91418 | O12: DL_HN_BACTULIEM | P12: VINMART Bắc Từ Liêm | Q12: Hà Nội | R12: Bắc Từ Liêm | S12: 21.052701 | T12: 105.78073 | U12: Nội thành Hà Nội | V12: Nội thành Hà Nội | W12: 26.2 | X12: 945 | Y12: 2.06 | Z12: 1 | AA12: 1.25T | AB12: 1.25T | AC12: No | AD12: Yes | AE12: No | AF12: Yes | AG12: Nội đô, khung giờ hạn chế xe tải | AH12: 07:00 | AI12: 09:00 | AJ12: 09:29 | AK12: 10:59 | AL12: 30 | AM12: 25 | AN12: 20 | AO12: 239 | AP12: 910000 | AQ12: 0 | AR12: 0 | AS12: 80000 | AT12: B - Thường | AU12: CR-NỘIT-02 | AV12: Hệ thống khách hàng | AW12: S1-C11 | AX12: 1.25T | AY12: Send to Clustering | AZ12: OK | BA12: Cấm tải/đường nhỏ - đã chọn xe nhỏ | BB12: =AM12+AN12 | BC12: =ROUND(W12/'03_Cost_Constraints'!$B$4*60,0) | BD12: =IF(X12<=500,"5 tạ",IF(X12<=1250,"1.25T",IF(X12<=5000,"5T",IF(X12<=8000,"8T",IF(X12<=15000,"3 chân","4 chân"))))) | BE12: =IF((BB12+BC12)<=AO12,"OK","Risk") | BF12: =IF(AND(AZ12="OK",BE12="OK"),"Ready","Review")
A13: S1 | B13: 2026-06-05 | C13: S1-ORD-012 | D13: VinCommerce | E13: TOPS MARKET Garden Mall | F13: MT | G13: EXPL | H13: Bia lon Saigon Export | I13: PK_LINFOX_VSIP | J13: Kho Linfox KCN VSIP Bắc Ninh | K13: Bắc Ninh | L13: Từ Sơn | M13: 21.082707 | N13: 105.99795 | O13: DL_HN_GARDEN | P13: TOPS MARKET Garden Mall | Q13: Hà Nội | R13: Nam Từ Liêm | S13: 21.015324 | T13: 105.77784 | U13: Nội thành Hà Nội | V13: Nội thành Hà Nội | W13: 39.8 | X13: 349 | Y13: 0.89 | Z13: 1 | AA13: 5 tạ | AB13: 1.25T | AC13: No | AD13: Yes | AE13: No | AF13: Yes | AG13: Khung giờ nhập kho cố định | AH13: 08:00 | AI13: 10:00 | AJ13: 10:23 | AK13: 13:23 | AL13: 45 | AM13: 25 | AN13: 30 | AO13: 323 | AP13: 510000 | AQ13: 150000 | AR13: 120000 | AS13: 80000 | AT13: B - Thường | AU13: CR-NỘIT-03 | AV13: Zalo/Email plan 17:00 | AW13: S1-C12 | AX13: 5 tạ | AY13: Send to Clustering | AZ13: OK | BA13: Cấm tải/đường nhỏ - đã chọn xe nhỏ | BB13: =AM13+AN13 | BC13: =ROUND(W13/'03_Cost_Constraints'!$B$4*60,0) | BD13: =IF(X13<=500,"5 tạ",IF(X13<=1250,"1.25T",IF(X13<=5000,"5T",IF(X13<=8000,"8T",IF(X13<=15000,"3 chân","4 chân"))))) | BE13: =IF((BB13+BC13)<=AO13,"OK","Risk") | BF13: =IF(AND(AZ13="OK",BE13="OK"),"Ready","Review") | BG13: Kế hoạch ngày hôm sau; cần chốt trước 19:00 và gửi tài xế sau duyệt
A14: S1 | B14: 2026-06-05 | C14: S1-ORD-013 | D14: VinCommerce | E14: Siêu thị Hải Dương | F14: ST | G14: CHCA | H14: Bia lon Saigon Chill | I14: PK_LINFOX_VSIP | J14: Kho Linfox KCN VSIP Bắc Ninh | K14: Bắc Ninh | L14: Từ Sơn | M14: 21.082707 | N14: 105.99795 | O14: DL_HD_SIEUTHI | P14: Siêu thị Hải Dương | Q14: Hải Phòng | R14: Hải Dương | S14: 20.937341 | T14: 106.31455 | U14: Đông Bắc | V14: Đông Bắc | W14: 49.4 | X14: 1820 | Y14: 2.93 | Z14: 2 | AA14: 5T | AB14: 8T | AC14: No | AD14: Yes | AE14: No | AF14: No | AG14: Quốc lộ 5, xe 8T vào được | AH14: 08:30 | AI14: 10:30 | AJ14: 12:05 | AK14: 15:05 | AL14: 45 | AM14: 40 | AN14: 35 | AO14: 395 | AP14: 910000 | AQ14: 0 | AR14: 0 | AS14: 80000 | AT14: C - Có thể thương lượng | AU14: CR-ĐÔNG-04 | AV14: Manual nhập điều phối | AW14: S1-C13 | AX14: 5T | AY14: Send to Clustering | AZ14: OK | BA14: OK | BB14: =AM14+AN14 | BC14: =ROUND(W14/'03_Cost_Constraints'!$B$4*60,0) | BD14: =IF(X14<=500,"5 tạ",IF(X14<=1250,"1.25T",IF(X14<=5000,"5T",IF(X14<=8000,"8T",IF(X14<=15000,"3 chân","4 chân"))))) | BE14: =IF((BB14+BC14)<=AO14,"OK","Risk") | BF14: =IF(AND(AZ14="OK",BE14="OK"),"Ready","Review")
A15: S1 | B15: 2026-06-05 | C15: S1-ORD-014 | D15: Sabeco | E15: LOTTE MART Ba Đình | F15: MT | G15: FMCG | H15: Hàng tiêu dùng nhanh hỗn hợp | I15: PK_HY_MYHAO | J15: Kho/Nhà máy khách hàng Mỹ Hào | K15: Hưng Yên | L15: Mỹ Hào | M15: 20.9329 | N15: 106.065 | O15: DL_HN_LOTTE_BD | P15: LOTTE MART Ba Đình | Q15: Hà Nội | R15: Ba Đình | S15: 21.032177 | T15: 105.81244 | U15: Nội thành Hà Nội | V15: Nội thành Hà Nội | W15: 47.7 | X15: 1392 | Y15: 4.83 | Z15: 4 | AA15: 5T | AB15: 1.25T | AC15: No | AD15: Yes | AE15: No | AF15: Yes | AG15: Giờ cấm tải, ưu tiên xe 1.25T | AH15: 09:00 | AI15: 11:30 | AJ15: 11:21 | AK15: 12:51 | AL15: 30 | AM15: 40 | AN15: 45 | AO15: 231 | AP15: 910000 | AQ15: 0 | AR15: 120000 | AS15: 80000 | AT15: C - Có thể thương lượng | AU15: CR-NỘIT-05 | AV15: Excel khách hàng | AW15: S1-C14 | AX15: Split/Chuyển tải | AY15: Split Order/Chuyển tải hoặc xin xe nhỏ nhiều chuyến | AZ15: Review | BA15: Vehicle Mismatch | BB15: =AM15+AN15 | BC15: =ROUND(W15/'03_Cost_Constraints'!$B$4*60,0) | BD15: =IF(X15<=500,"5 tạ",IF(X15<=1250,"1.25T",IF(X15<=5000,"5T",IF(X15<=8000,"8T",IF(X15<=15000,"3 chân","4 chân"))))) | BE15: =IF((BB15+BC15)<=AO15,"OK","Risk") | BF15: =IF(AND(AZ15="OK",BE15="OK"),"Ready","Review")
A16: S1 | B16: 2026-06-05 | C16: S1-ORD-015 | D16: Acecook | E16: VINMART Trương Định | F16: ST | G16: CHCA | H16: Bia lon Saigon Chill | I16: PK_HPL_LB | J16: HPL Depot Long Biên - 20 Thạch Bàn | K16: Hà Nội | L16: Long Biên | M16: 21.026155 | N16: 105.91418 | O16: DL_HN_TRUONGDINH | P16: VINMART Trương Định | Q16: Hà Nội | R16: Hoàng Mai | S16: 20.979293 | T16: 105.84471 | U16: Nội thành Hà Nội | V16: Nội thành Hà Nội | W16: 17 | X16: 914 | Y16: 2 | Z16: 1 | AA16: 1.25T | AB16: 1.25T | AC16: No | AD16: Yes | AE16: No | AF16: Yes | AG16: Đường nhỏ, khó quay đầu | AH16: 09:00 | AI16: 10:30 | AJ16: 11:44 | AK16: 13:14 | AL16: 45 | AM16: 25 | AN16: 20 | AO16: 254 | AP16: 520000 | AQ16: 150000 | AR16: 0 | AS16: 80000 | AT16: C - Có thể thương lượng | AU16: CR-NỘIT-01 | AV16: Hệ thống khách hàng | AW16: S1-C15 | AX16: 1.25T | AY16: Send to Clustering | AZ16: OK | BA16: Cấm tải/đường nhỏ - đã chọn xe nhỏ | BB16: =AM16+AN16 | BC16: =ROUND(W16/'03_Cost_Constraints'!$B$4*60,0) | BD16: =IF(X16<=500,"5 tạ",IF(X16<=1250,"1.25T",IF(X16<=5000,"5T",IF(X16<=8000,"8T",IF(X16<=15000,"3 chân","4 chân"))))) | BE16: =IF((BB16+BC16)<=AO16,"OK","Risk") | BF16: =IF(AND(AZ16="OK",BE16="OK"),"Ready","Review")
A17: S1 | B17: 2026-06-05 | C17: S1-ORD-016 | D17: Linfox | E17: VINMART Hoài Đức | F17: ST | G17: NOODLE | H17: Mì gói/Acecook carton | I17: PK_LINFOX_VSIP | J17: Kho Linfox KCN VSIP Bắc Ninh | K17: Bắc Ninh | L17: Từ Sơn | M17: 21.082707 | N17: 105.99795 | O17: DL_HN_HOAIDUC | P17: VINMART Hoài Đức | Q17: Hà Nội | R17: Hoài Đức | S17: 21.005046 | T17: 105.72829 | U17: Tây Bắc | V17: Tây Bắc | W17: 43.7 | X17: 7741 | Y17: 70.3 | Z17: 58 | AA17: 4 chân | AB17: 5T | AC17: No | AD17: Yes | AE17: No | AF17: No | AG17: Ngoại thành, xe 5T vào được | AH17: 08:30 | AI17: 11:00 | AJ17: 13:18 | AK17: 15:48 | AL17: 45 | AM17: 120 | AN17: 90 | AO17: 438 | AP17: 2200000 | AQ17: 0 | AR17: 0 | AS17: 80000 | AT17: B - Thường | AU17: CR-TÂYB-02 | AV17: Zalo/Email plan 17:00 | AW17: S1-C16 | AX17: Split/Chuyển tải | AY17: Split Order/Chuyển tải hoặc xin xe nhỏ nhiều chuyến | AZ17: Review | BA17: Vehicle Mismatch | BB17: =AM17+AN17 | BC17: =ROUND(W17/'03_Cost_Constraints'!$B$4*60,0) | BD17: =IF(X17<=500,"5 tạ",IF(X17<=1250,"1.25T",IF(X17<=5000,"5T",IF(X17<=8000,"8T",IF(X17<=15000,"3 chân","4 chân"))))) | BE17: =IF((BB17+BC17)<=AO17,"OK","Risk") | BF17: =IF(AND(AZ17="OK",BE17="OK"),"Ready","Review") | BG17: Kế hoạch ngày hôm sau; cần chốt trước 19:00 và gửi tài xế sau duyệt
A18: S1 | B18: 2026-06-05 | C18: S1-ORD-017 | D18: MM Mega Market | E18: Nam Dương | F18: Đại lý | G18: MILK | H18: Sữa hộp carton | I18: PK_HPL_LB | J18: HPL Depot Long Biên - 20 Thạch Bàn | K18: Hà Nội | L18: Long Biên | M18: 21.026155 | N18: 105.91418 | O18: DL_HN_NAMDUONG | P18: Nam Dương | Q18: Hà Nội | R18: Hà Nội | S18: 21.062911 | T18: 105.83235 | U18: Nội thành Hà Nội | V18: Nội thành Hà Nội | W18: 18.4 | X18: 1076 | Y18: 2.93 | Z18: 2 | AA18: 1.25T | AB18: 1.25T | AC18: No | AD18: Yes | AE18: No | AF18: Yes | AG18: Đường nội đô, có khung giờ cấm tải | AH18: 07:30 | AI18: 09:30 | AJ18: 10:16 | AK18: 12:16 | AL18: 30 | AM18: 25 | AN18: 20 | AO18: 286 | AP18: 890000 | AQ18: 0 | AR18: 0 | AS18: 80000 | AT18: B - Thường | AU18: CR-NỘIT-03 | AV18: Manual nhập điều phối | AW18: S1-C16 | AX18: 1.25T | AY18: Send to Clustering | AZ18: OK | BA18: Cấm tải/đường nhỏ - đã chọn xe nhỏ | BB18: =AM18+AN18 | BC18: =ROUND(W18/'03_Cost_Constraints'!$B$4*60,0) | BD18: =IF(X18<=500,"5 tạ",IF(X18<=1250,"1.25T",IF(X18<=5000,"5T",IF(X18<=8000,"8T",IF(X18<=15000,"3 chân","4 chân"))))) | BE18: =IF((BB18+BC18)<=AO18,"OK","Risk") | BF18: =IF(AND(AZ18="OK",BE18="OK"),"Ready","Review")
A19: S1 | B19: 2026-06-05 | C19: S1-ORD-018 | D19: Linfox | E19: LOTTE MART Ba Đình | F19: MT | G19: PAT2 | H19: Bia lon 333 | I19: PK_HY_MYHAO | J19: Kho/Nhà máy khách hàng Mỹ Hào | K19: Hưng Yên | L19: Mỹ Hào | M19: 20.9329 | N19: 106.065 | O19: DL_HN_LOTTE_BD | P19: LOTTE MART Ba Đình | Q19: Hà Nội | R19: Ba Đình | S19: 21.032177 | T19: 105.81244 | U19: Nội thành Hà Nội | V19: Nội thành Hà Nội | W19: 48.9 | X19: 670 | Y19: 1.57 | Z19: 1 | AA19: 1.25T | AB19: 1.25T | AC19: No | AD19: Yes | AE19: No | AF19: Yes | AG19: Giờ cấm tải, ưu tiên xe 1.25T | AH19: 07:30 | AI19: 09:00 | AJ19: 09:38 | AK19: 12:08 | AL19: 45 | AM19: 25 | AN19: 30 | AO19: 278 | AP19: 750000 | AQ19: 150000 | AR19: 120000 | AS19: 80000 | AT19: B - Thường | AU19: CR-NỘIT-04 | AV19: Excel khách hàng | AW19: S1-C18 | AX19: 1.25T | AY19: Send to Clustering | AZ19: OK | BA19: Cấm tải/đường nhỏ - đã chọn xe nhỏ | BB19: =AM19+AN19 | BC19: =ROUND(W19/'03_Cost_Constraints'!$B$4*60,0) | BD19: =IF(X19<=500,"5 tạ",IF(X19<=1250,"1.25T",IF(X19<=5000,"5T",IF(X19<=8000,"8T",IF(X19<=15000,"3 chân","4 chân"))))) | BE19: =IF((BB19+BC19)<=AO19,"OK","Risk") | BF19: =IF(AND(AZ19="OK",BE19="OK"),"Ready","Review")
A20: S1 | B20: 2026-06-05 | C20: S1-ORD-019 | D20: Bách Hóa Xanh | E20: VINMART Royal City | F20: MT | G20: PAT2 | H20: Bia lon 333 | I20: PK_HPL_LB | J20: HPL Depot Long Biên - 20 Thạch Bàn | K20: Hà Nội | L20: Long Biên | M20: 21.026155 | N20: 105.91418 | O20: DL_HN_ROYAL | P20: VINMART Royal City | Q20: Hà Nội | R20: Thanh Xuân | S20: 21.003388 | T20: 105.81621 | U20: Nội thành Hà Nội | V20: Nội thành Hà Nội | W20: 22.1 | X20: 1179 | Y20: 2.33 | Z20: 1 | AA20: 1.25T | AB20: 1.25T | AC20: No | AD20: Yes | AE20: No | AF20: Yes | AG20: Hầm trung tâm thương mại | AH20: 08:30 | AI20: 10:30 | AJ20: 09:52 | AK20: 11:52 | AL20: 45 | AM20: 25 | AN20: 30 | AO20: 202 | AP20: 720000 | AQ20: 0 | AR20: 120000 | AS20: 150000 | AT20: A - SLA chặt | AU20: CR-NỘIT-05 | AV20: Hệ thống khách hàng | AW20: S1-C19 | AX20: 1.25T | AY20: Send to Clustering | AZ20: OK | BA20: Cấm tải/đường nhỏ - đã chọn xe nhỏ | BB20: =AM20+AN20 | BC20: =ROUND(W20/'03_Cost_Constraints'!$B$4*60,0) | BD20: =IF(X20<=500,"5 tạ",IF(X20<=1250,"1.25T",IF(X20<=5000,"5T",IF(X20<=8000,"8T",IF(X20<=15000,"3 chân","4 chân"))))) | BE20: =IF((BB20+BC20)<=AO20,"OK","Risk") | BF20: =IF(AND(AZ20="OK",BE20="OK"),"Ready","Review")
A21: S1 | B21: 2026-06-05 | C21: S1-ORD-020 | D21: MM Mega Market | E21: Siêu thị Hải Dương | F21: ST | G21: EXPL | H21: Bia lon Saigon Export | I21: PK_LINFOX_VSIP | J21: Kho Linfox KCN VSIP Bắc Ninh | K21: Bắc Ninh | L21: Từ Sơn | M21: 21.082707 | N21: 105.99795 | O21: DL_HD_SIEUTHI | P21: Siêu thị Hải Dương | Q21: Hải Phòng | R21: Hải Dương | S21: 20.937341 | T21: 106.31455 | U21: Đông Bắc | V21: Đông Bắc | W21: 51 | X21: 6453 | Y21: 16.2 | Z21: 13 | AA21: 8T | AB21: 8T | AC21: No | AD21: Yes | AE21: No | AF21: No | AG21: Quốc lộ 5, xe 8T vào được | AH21: 08:30 | AI21: 10:30 | AJ21: 11:08 | AK21: 13:08 | AL21: 30 | AM21: 40 | AN21: 35 | AO21: 278 | AP21: 2510000 | AQ21: 0 | AR21: 0 | AS21: 150000 | AT21: A - SLA chặt | AU21: CR-ĐÔNG-01 | AV21: Zalo/Email plan 17:00 | AW21: S1-C20 | AX21: 8T | AY21: Send to Clustering | AZ21: OK | BA21: OK | BB21: =AM21+AN21 | BC21: =ROUND(W21/'03_Cost_Constraints'!$B$4*60,0) | BD21: =IF(X21<=500,"5 tạ",IF(X21<=1250,"1.25T",IF(X21<=5000,"5T",IF(X21<=8000,"8T",IF(X21<=15000,"3 chân","4 chân"))))) | BE21: =IF((BB21+BC21)<=AO21,"OK","Risk") | BF21: =IF(AND(AZ21="OK",BE21="OK"),"Ready","Review") | BG21: Kế hoạch ngày hôm sau; cần chốt trước 19:00 và gửi tài xế sau duyệt
A22: S1 | B22: 2026-06-05 | C22: S1-ORD-021 | D22: Unilever | E22: VINMART Uông Bí | F22: ST | G22: PAT2 | H22: Bia lon 333 | I22: PK_LINFOX_VSIP | J22: Kho Linfox KCN VSIP Bắc Ninh | K22: Bắc Ninh | L22: Từ Sơn | M22: 21.082707 | N22: 105.99795 | O22: DL_QN_UONGBI | P22: VINMART Uông Bí | Q22: Quảng Ninh | R22: Uông Bí | S22: 21.031495 | T22: 106.76688 | U22: Đông Bắc | V22: Đông Bắc | W22: 105.5 | X22: 1872 | Y22: 3.67 | Z22: 3 | AA22: 5T | AB22: 8T | AC22: No | AD22: Yes | AE22: No | AF22: No | AG22: Đường tỉnh, xe 5T/8T vào được | AH22: 08:30 | AI22: 10:30 | AJ22: 13:20 | AK22: 14:50 | AL22: 45 | AM22: 40 | AN22: 35 | AO22: 380 | AP22: 1820000 | AQ22: 150000 | AR22: 0 | AS22: 80000 | AT22: C - Có thể thương lượng | AU22: CR-ĐÔNG-02 | AV22: Manual nhập điều phối | AW22: S1-C21 | AX22: 5T | AY22: Send to Clustering | AZ22: OK | BA22: Empty-run >100km cần tìm chuyến về | BB22: =AM22+AN22 | BC22: =ROUND(W22/'03_Cost_Constraints'!$B$4*60,0) | BD22: =IF(X22<=500,"5 tạ",IF(X22<=1250,"1.25T",IF(X22<=5000,"5T",IF(X22<=8000,"8T",IF(X22<=15000,"3 chân","4 chân"))))) | BE22: =IF((BB22+BC22)<=AO22,"OK","Risk") | BF22: =IF(AND(AZ22="OK",BE22="OK"),"Ready","Review")
A23: S1 | B23: 2026-06-05 | C23: S1-ORD-022 | D23: VinCommerce | E23: TOPS MARKET Garden Mall | F23: MT | G23: LVCA | H23: Bia lon Lạc Việt | I23: PK_LINFOX_VSIP | J23: Kho Linfox KCN VSIP Bắc Ninh | K23: Bắc Ninh | L23: Từ Sơn | M23: 21.082707 | N23: 105.99795 | O23: DL_HN_GARDEN | P23: TOPS MARKET Garden Mall | Q23: Hà Nội | R23: Nam Từ Liêm | S23: 21.015324 | T23: 105.77784 | U23: Nội thành Hà Nội | V23: Nội thành Hà Nội | W23: 38.4 | X23: 1345 | Y23: 3.52 | Z23: 2 | AA23: 5T | AB23: 1.25T | AC23: No | AD23: Yes | AE23: No | AF23: Yes | AG23: Khung giờ nhập kho cố định | AH23: 09:00 | AI23: 10:30 | AJ23: 12:05 | AK23: 14:05 | AL23: 45 | AM23: 40 | AN23: 45 | AO23: 305 | AP23: 690000 | AQ23: 0 | AR23: 120000 | AS23: 80000 | AT23: C - Có thể thương lượng | AU23: CR-NỘIT-03 | AV23: Excel khách hàng | AW23: S1-C22 | AX23: Split/Chuyển tải | AY23: Split Order/Chuyển tải hoặc xin xe nhỏ nhiều chuyến | AZ23: Review | BA23: Vehicle Mismatch | BB23: =AM23+AN23 | BC23: =ROUND(W23/'03_Cost_Constraints'!$B$4*60,0) | BD23: =IF(X23<=500,"5 tạ",IF(X23<=1250,"1.25T",IF(X23<=5000,"5T",IF(X23<=8000,"8T",IF(X23<=15000,"3 chân","4 chân"))))) | BE23: =IF((BB23+BC23)<=AO23,"OK","Risk") | BF23: =IF(AND(AZ23="OK",BE23="OK"),"Ready","Review")
A24: S1 | B24: 2026-06-05 | C24: S1-ORD-023 | D24: Acecook | E24: Siêu thị Hải Phòng | F24: MT | G24: EXPL | H24: Bia lon Saigon Export | I24: PK_HP_DINHVU | J24: Kho Hải Phòng - Đình Vũ | K24: Hải Phòng | L24: Hải An | M24: 20.8425 | N24: 106.77 | O24: DL_HP_SIEUTHI | P24: Siêu thị Hải Phòng | Q24: Hải Phòng | R24: Gia Viên | S24: 20.84442 | T24: 106.7011 | U24: Đông Bắc | V24: Đông Bắc | W24: 13.2 | X24: 1219 | Y24: 2.74 | Z24: 2 | AA24: 1.25T | AB24: 5T | AC24: No | AD24: Yes | AE24: No | AF24: No | AG24: Khung giờ nhập kho 13:00-16:00 | AH24: 08:00 | AI24: 10:30 | AJ24: 09:32 | AK24: 12:02 | AL24: 45 | AM24: 25 | AN24: 30 | AO24: 242 | AP24: 530000 | AQ24: 0 | AR24: 120000 | AS24: 150000 | AT24: A - SLA chặt | AU24: CR-ĐÔNG-04 | AV24: Hệ thống khách hàng | AW24: S1-C23 | AX24: 1.25T | AY24: Send to Clustering | AZ24: OK | BA24: OK | BB24: =AM24+AN24 | BC24: =ROUND(W24/'03_Cost_Constraints'!$B$4*60,0) | BD24: =IF(X24<=500,"5 tạ",IF(X24<=1250,"1.25T",IF(X24<=5000,"5T",IF(X24<=8000,"8T",IF(X24<=15000,"3 chân","4 chân"))))) | BE24: =IF((BB24+BC24)<=AO24,"OK","Risk") | BF24: =IF(AND(AZ24="OK",BE24="OK"),"Ready","Review")
A25: S1 | B25: 2026-06-05 | C25: S1-ORD-024 | D25: Acecook | E25: LOTTE MART Đống Đa | F25: MT | G25: NOODLE | H25: Mì gói/Acecook carton | I25: PK_HY_MYHAO | J25: Kho/Nhà máy khách hàng Mỹ Hào | K25: Hưng Yên | L25: Mỹ Hào | M25: 20.9329 | N25: 106.065 | O25: DL_HN_LOTTE_DD | P25: LOTTE MART Đống Đa | Q25: Hà Nội | R25: Đống Đa | S25: 21.005536 | T25: 105.82394 | U25: Nội thành Hà Nội | V25: Nội thành Hà Nội | W25: 44.3 | X25: 1402 | Y25: 8.84 | Z25: 7 | AA25: 5T | AB25: 1.25T | AC25: No | AD25: Yes | AE25: No | AF25: Yes | AG25: Hầm giao nhận, chỉ xe nhỏ/1.25T | AH25: 07:00 | AI25: 08:30 | AJ25: 10:15 | AK25: 13:15 | AL25: 45 | AM25: 40 | AN25: 45 | AO25: 375 | AP25: 1090000 | AQ25: 150000 | AR25: 120000 | AS25: 150000 | AT25: A - SLA chặt | AU25: CR-NỘIT-05 | AV25: Zalo/Email plan 17:00 | AW25: S1-C24 | AX25: Split/Chuyển tải | AY25: Split Order/Chuyển tải hoặc xin xe nhỏ nhiều chuyến | AZ25: Review | BA25: Vehicle Mismatch | BB25: =AM25+AN25 | BC25: =ROUND(W25/'03_Cost_Constraints'!$B$4*60,0) | BD25: =IF(X25<=500,"5 tạ",IF(X25<=1250,"1.25T",IF(X25<=5000,"5T",IF(X25<=8000,"8T",IF(X25<=15000,"3 chân","4 chân"))))) | BE25: =IF((BB25+BC25)<=AO25,"OK","Risk") | BF25: =IF(AND(AZ25="OK",BE25="OK"),"Ready","Review") | BG25: Kế hoạch ngày hôm sau; cần chốt trước 19:00 và gửi tài xế sau duyệt
A26: S1 | B26: 2026-06-05 | C26: S1-ORD-025 | D26: MM Mega Market | E26: VINMART Bắc Từ Liêm | F26: ST | G26: CHCA | H26: Bia lon Saigon Chill | I26: PK_LINFOX_VSIP | J26: Kho Linfox KCN VSIP Bắc Ninh | K26: Bắc Ninh | L26: Từ Sơn | M26: 21.082707 | N26: 105.99795 | O26: DL_HN_BACTULIEM | P26: VINMART Bắc Từ Liêm | Q26: Hà Nội | R26: Bắc Từ Liêm | S26: 21.052701 | T26: 105.78073 | U26: Nội thành Hà Nội | V26: Nội thành Hà Nội | W26: 40.4 | X26: 988 | Y26: 1.61 | Z26: 1 | AA26: 1.25T | AB26: 1.25T | AC26: No | AD26: Yes | AE26: No | AF26: Yes | AG26: Nội đô, khung giờ hạn chế xe tải | AH26: 09:00 | AI26: 11:30 | AJ26: 12:24 | AK26: 15:24 | AL26: 30 | AM26: 25 | AN26: 20 | AO26: 384 | AP26: 780000 | AQ26: 0 | AR26: 0 | AS26: 80000 | AT26: B - Thường | AU26: CR-NỘIT-01 | AV26: Manual nhập điều phối | AW26: S1-C25 | AX26: 1.25T | AY26: Send to Clustering | AZ26: OK | BA26: Cấm tải/đường nhỏ - đã chọn xe nhỏ | BB26: =AM26+AN26 | BC26: =ROUND(W26/'03_Cost_Constraints'!$B$4*60,0) | BD26: =IF(X26<=500,"5 tạ",IF(X26<=1250,"1.25T",IF(X26<=5000,"5T",IF(X26<=8000,"8T",IF(X26<=15000,"3 chân","4 chân"))))) | BE26: =IF((BB26+BC26)<=AO26,"OK","Risk") | BF26: =IF(AND(AZ26="OK",BE26="OK"),"Ready","Review")
A27: S1 | B27: 2026-06-05 | C27: S1-ORD-026 | D27: Linfox | E27: TOPS MARKET Garden Mall | F27: MT | G27: POSM | H27: POSM trưng bày | I27: PK_HPL_LB | J27: HPL Depot Long Biên - 20 Thạch Bàn | K27: Hà Nội | L27: Long Biên | M27: 21.026155 | N27: 105.91418 | O27: DL_HN_GARDEN | P27: TOPS MARKET Garden Mall | Q27: Hà Nội | R27: Nam Từ Liêm | S27: 21.015324 | T27: 105.77784 | U27: Nội thành Hà Nội | V27: Nội thành Hà Nội | W27: 22.5 | X27: 1043 | Y27: 22.83 | Z27: 19 | AA27: 5T | AB27: 1.25T | AC27: No | AD27: Yes | AE27: No | AF27: Yes | AG27: Khung giờ nhập kho cố định | AH27: 09:00 | AI27: 10:30 | AJ27: 10:38 | AK27: 13:08 | AL27: 45 | AM27: 40 | AN27: 45 | AO27: 248 | AP27: 710000 | AQ27: 0 | AR27: 120000 | AS27: 80000 | AT27: C - Có thể thương lượng | AU27: CR-NỘIT-02 | AV27: Excel khách hàng | AW27: S1-C26 | AX27: Split/Chuyển tải | AY27: Split Order/Chuyển tải hoặc xin xe nhỏ nhiều chuyến | AZ27: Review | BA27: Vehicle Mismatch | BB27: =AM27+AN27 | BC27: =ROUND(W27/'03_Cost_Constraints'!$B$4*60,0) | BD27: =IF(X27<=500,"5 tạ",IF(X27<=1250,"1.25T",IF(X27<=5000,"5T",IF(X27<=8000,"8T",IF(X27<=15000,"3 chân","4 chân"))))) | BE27: =IF((BB27+BC27)<=AO27,"OK","Risk") | BF27: =IF(AND(AZ27="OK",BE27="OK"),"Ready","Review")
A28: S1 | B28: 2026-06-05 | C28: S1-ORD-027 | D28: Bách Hóa Xanh | E28: Siêu thị Hải Phòng | F28: MT | G28: FMCG | H28: Hàng tiêu dùng nhanh hỗn hợp | I28: PK_HP_DINHVU | J28: Kho Hải Phòng - Đình Vũ | K28: Hải Phòng | L28: Hải An | M28: 20.8425 | N28: 106.77 | O28: DL_HP_SIEUTHI | P28: Siêu thị Hải Phòng | Q28: Hải Phòng | R28: Gia Viên | S28: 20.84442 | T28: 106.7011 | U28: Đông Bắc | V28: Đông Bắc | W28: 13.1 | X28: 1775 | Y28: 9.34 | Z28: 7 | AA28: 5T | AB28: 5T | AC28: No | AD28: Yes | AE28: No | AF28: No | AG28: Khung giờ nhập kho 13:00-16:00 | AH28: 08:00 | AI28: 10:30 | AJ28: 10:17 | AK28: 12:47 | AL28: 45 | AM28: 40 | AN28: 45 | AO28: 287 | AP28: 720000 | AQ28: 150000 | AR28: 120000 | AS28: 80000 | AT28: B - Thường | AU28: CR-ĐÔNG-03 | AV28: Hệ thống khách hàng | AW28: S1-C27 | AX28: 5T | AY28: Send to Clustering | AZ28: OK | BA28: OK | BB28: =AM28+AN28 | BC28: =ROUND(W28/'03_Cost_Constraints'!$B$4*60,0) | BD28: =IF(X28<=500,"5 tạ",IF(X28<=1250,"1.25T",IF(X28<=5000,"5T",IF(X28<=8000,"8T",IF(X28<=15000,"3 chân","4 chân"))))) | BE28: =IF((BB28+BC28)<=AO28,"OK","Risk") | BF28: =IF(AND(AZ28="OK",BE28="OK"),"Ready","Review")
A29: S1 | B29: 2026-06-05 | C29: S1-ORD-028 | D29: MM Mega Market | E29: LOTTE MART Đống Đa | F29: MT | G29: POSM | H29: POSM trưng bày | I29: PK_HPL_LB | J29: HPL Depot Long Biên - 20 Thạch Bàn | K29: Hà Nội | L29: Long Biên | M29: 21.026155 | N29: 105.91418 | O29: DL_HN_LOTTE_DD | P29: LOTTE MART Đống Đa | Q29: Hà Nội | R29: Đống Đa | S29: 21.005536 | T29: 105.82394 | U29: Nội thành Hà Nội | V29: Nội thành Hà Nội | W29: 16.1 | X29: 1438 | Y29: 37.08 | Z29: 30 | AA29: 8T | AB29: 1.25T | AC29: No | AD29: Yes | AE29: No | AF29: Yes | AG29: Hầm giao nhận, chỉ xe nhỏ/1.25T | AH29: 08:30 | AI29: 11:00 | AJ29: 09:57 | AK29: 12:27 | AL29: 30 | AM29: 40 | AN29: 45 | AO29: 237 | AP29: 700000 | AQ29: 0 | AR29: 120000 | AS29: 80000 | AT29: C - Có thể thương lượng | AU29: CR-NỘIT-04 | AV29: Zalo/Email plan 17:00 | AW29: S1-C28 | AX29: Split/Chuyển tải | AY29: Split Order/Chuyển tải hoặc xin xe nhỏ nhiều chuyến | AZ29: Review | BA29: Vehicle Mismatch | BB29: =AM29+AN29 | BC29: =ROUND(W29/'03_Cost_Constraints'!$B$4*60,0) | BD29: =IF(X29<=500,"5 tạ",IF(X29<=1250,"1.25T",IF(X29<=5000,"5T",IF(X29<=8000,"8T",IF(X29<=15000,"3 chân","4 chân"))))) | BE29: =IF((BB29+BC29)<=AO29,"OK","Risk") | BF29: =IF(AND(AZ29="OK",BE29="OK"),"Ready","Review") | BG29: Kế hoạch ngày hôm sau; cần chốt trước 19:00 và gửi tài xế sau duyệt
A30: S1 | B30: 2026-06-05 | C30: S1-ORD-029 | D30: Masan | E30: VINMART Times City | F30: MT | G30: PAT2 | H30: Bia lon 333 | I30: PK_HPL_LB | J30: HPL Depot Long Biên - 20 Thạch Bàn | K30: Hà Nội | L30: Long Biên | M30: 21.026155 | N30: 105.91418 | O30: DL_HN_TIMESCITY | P30: VINMART Times City | Q30: Hà Nội | R30: Hai Bà Trưng | S30: 20.994022 | T30: 105.86964 | U30: Nội thành Hà Nội | V30: Nội thành Hà Nội | W30: 14.4 | X30: 223 | Y30: 0.6 | Z30: 1 | AA30: 5 tạ | AB30: 1.25T | AC30: No | AD30: Yes | AE30: No | AF30: Yes | AG30: Nội khu, xe lớn hạn chế | AH30: 07:00 | AI30: 09:30 | AJ30: 08:09 | AK30: 10:39 | AL30: 30 | AM30: 25 | AN30: 30 | AO30: 219 | AP30: 610000 | AQ30: 0 | AR30: 120000 | AS30: 80000 | AT30: B - Thường | AU30: CR-NỘIT-05 | AV30: Manual nhập điều phối | AW30: S1-C02 | AX30: 5 tạ | AY30: Send to Clustering | AZ30: OK | BA30: Cấm tải/đường nhỏ - đã chọn xe nhỏ | BB30: =AM30+AN30 | BC30: =ROUND(W30/'03_Cost_Constraints'!$B$4*60,0) | BD30: =IF(X30<=500,"5 tạ",IF(X30<=1250,"1.25T",IF(X30<=5000,"5T",IF(X30<=8000,"8T",IF(X30<=15000,"3 chân","4 chân"))))) | BE30: =IF((BB30+BC30)<=AO30,"OK","Risk") | BF30: =IF(AND(AZ30="OK",BE30="OK"),"Ready","Review")
A31: S1 | B31: 2026-06-05 | C31: S1-ORD-030 | D31: Sabeco | E31: Siêu thị Hải Phòng | F31: MT | G31: LVCA | H31: Bia lon Lạc Việt | I31: PK_LINFOX_VSIP | J31: Kho Linfox KCN VSIP Bắc Ninh | K31: Bắc Ninh | L31: Từ Sơn | M31: 21.082707 | N31: 105.99795 | O31: DL_HP_SIEUTHI | P31: Siêu thị Hải Phòng | Q31: Hải Phòng | R31: Gia Viên | S31: 20.84442 | T31: 106.7011 | U31: Đông Bắc | V31: Đông Bắc | W31: 102.4 | X31: 4789 | Y31: 12.42 | Z31: 10 | AA31: 5T | AB31: 5T | AC31: No | AD31: Yes | AE31: No | AF31: No | AG31: Khung giờ nhập kho 13:00-16:00 | AH31: 08:00 | AI31: 10:30 | AJ31: 11:16 | AK31: 13:46 | AL31: 30 | AM31: 40 | AN31: 45 | AO31: 346 | AP31: 3350000 | AQ31: 150000 | AR31: 120000 | AS31: 150000 | AT31: A - SLA chặt | AU31: CR-ĐÔNG-01 | AV31: Excel khách hàng | AW31: S1-C03 | AX31: 5T | AY31: Send to Clustering | AZ31: OK | BA31: Empty-run >100km cần tìm chuyến về | BB31: =AM31+AN31 | BC31: =ROUND(W31/'03_Cost_Constraints'!$B$4*60,0) | BD31: =IF(X31<=500,"5 tạ",IF(X31<=1250,"1.25T",IF(X31<=5000,"5T",IF(X31<=8000,"8T",IF(X31<=15000,"3 chân","4 chân"))))) | BE31: =IF((BB31+BC31)<=AO31,"OK","Risk") | BF31: =IF(AND(AZ31="OK",BE31="OK"),"Ready","Review")

Sheet S2_DapUng_Du
A1: Scenario_ID | B1: Planning_Date | C1: Order_ID | D1: Customer_Group | E1: Customer_Name | F1: Channel | G1: SKU_Code | H1: Product_Group | I1: Pickup_ID | J1: Pickup_Name | K1: Pickup_Province | L1: Pickup_District | M1: Pickup_Lat | N1: Pickup_Lon | O1: Delivery_ID | P1: Delivery_Name | Q1: Delivery_Province | R1: Delivery_District | S1: Delivery_Lat | T1: Delivery_Lon | U1: Corridor | V1: Route_Axis | W1: Direct_Distance_km | X1: Weight_kg | Y1: Volume_m3 | Z1: Pallet_Qty | AA1: Min_Vehicle_Type | AB1: Max_Vehicle_Type_Allowed | AC1: Required_Refrigeration | AD1: Can_Consolidate | AE1: Dedicated_Vehicle | AF1: Inner_City_Restriction | AG1: Access_Note | AH1: Pickup_TW_Start | AI1: Pickup_TW_End | AJ1: Drop_TW_Start | AK1: Drop_TW_End | AL1: TW_Flex_Min | AM1: Pickup_Service_Min | AN1: Drop_Service_Min | AO1: Lead_Time_Min | AP1: Freight_Revenue_VND | AQ1: Extra_Stop_Fee_VND | AR1: Waiting_Fee_Chargeable_VND | AS1: Late_Penalty_VND_per_30m | AT1: Customer_Priority | AU1: Contract_Route_ID | AV1: Source_System | AW1: Seed_Cluster_ID | AX1: Suggested_Vehicle_Type | AY1: Suggested_Action | AZ1: Validation_Status | BA1: Risk_Flag | BB1: Total_Service_Min | BC1: Direct_Drive_Min | BD1: Load_Class_kg | BE1: LeadTime_Check | BF1: Algorithm_Ready_Flag | BG1: Notes
A2: S2 | B2: 2026-06-05 | C2: S2-ORD-001 | D2: Sabeco | E2: AKJUKY | F2: Đại lý | G2: EXPL | H2: Bia lon Saigon Export | I2: PK_LINFOX_VSIP | J2: Kho Linfox KCN VSIP Bắc Ninh | K2: Bắc Ninh | L2: Từ Sơn | M2: 21.082707 | N2: 105.99795 | O2: DL_HN_AKJUKY | P2: AKJUKY | Q2: Hà Nội | R2: Long Biên | S2: 21.063695 | T2: 105.88999 | U2: Nội thành Hà Nội | V2: Nội thành Hà Nội | W2: 19.8 | X2: 371 | Y2: 0.67 | Z2: 1 | AA2: 5 tạ | AB2: 1.25T | AC2: No | AD2: No | AE2: Yes | AF2: Yes | AG2: Đường nhỏ nội đô | AH2: 08:00 | AI2: 09:30 | AJ2: 09:48 | AK2: 12:48 | AL2: 30 | AM2: 25 | AN2: 20 | AO2: 288 | AP2: 480000 | AQ2: 0 | AR2: 0 | AS2: 150000 | AT2: A - SLA chặt | AU2: CR-NỘIT-02 | AV2: Manual nhập điều phối | AW2: S2-C01 | AX2: 5 tạ | AY2: Send to Clustering | AZ2: OK | BA2: Cấm tải/đường nhỏ - đã chọn xe nhỏ | BB2: =AM2+AN2 | BC2: =ROUND(W2/'03_Cost_Constraints'!$B$4*60,0) | BD2: =IF(X2<=500,"5 tạ",IF(X2<=1250,"1.25T",IF(X2<=5000,"5T",IF(X2<=8000,"8T",IF(X2<=15000,"3 chân","4 chân"))))) | BE2: =IF((BB2+BC2)<=AO2,"OK","Risk") | BF2: =IF(AND(AZ2="OK",BE2="OK"),"Ready","Review")
A3: S2 | B3: 2026-06-05 | C3: S2-ORD-002 | D3: Linfox | E3: VINMART Royal City | F3: MT | G3: PAT2 | H3: Bia lon 333 | I3: PK_HPL_LB | J3: HPL Depot Long Biên - 20 Thạch Bàn | K3: Hà Nội | L3: Long Biên | M3: 21.026155 | N3: 105.91418 | O3: DL_HN_ROYAL | P3: VINMART Royal City | Q3: Hà Nội | R3: Thanh Xuân | S3: 21.003388 | T3: 105.81621 | U3: Nội thành Hà Nội | V3: Nội thành Hà Nội | W3: 19.1 | X3: 386 | Y3: 1.11 | Z3: 1 | AA3: 5 tạ | AB3: 1.25T | AC3: No | AD3: Yes | AE3: No | AF3: Yes | AG3: Hầm trung tâm thương mại | AH3: 08:00 | AI3: 10:30 | AJ3: 09:47 | AK3: 12:17 | AL3: 45 | AM3: 25 | AN3: 30 | AO3: 257 | AP3: 830000 | AQ3: 0 | AR3: 120000 | AS3: 150000 | AT3: A - SLA chặt | AU3: CR-NỘIT-03 | AV3: Excel khách hàng | AW3: S2-C02 | AX3: 5 tạ | AY3: Send to Clustering | AZ3: OK | BA3: Cấm tải/đường nhỏ - đã chọn xe nhỏ | BB3: =AM3+AN3 | BC3: =ROUND(W3/'03_Cost_Constraints'!$B$4*60,0) | BD3: =IF(X3<=500,"5 tạ",IF(X3<=1250,"1.25T",IF(X3<=5000,"5T",IF(X3<=8000,"8T",IF(X3<=15000,"3 chân","4 chân"))))) | BE3: =IF((BB3+BC3)<=AO3,"OK","Risk") | BF3: =IF(AND(AZ3="OK",BE3="OK"),"Ready","Review")
A4: S2 | B4: 2026-06-05 | C4: S2-ORD-003 | D4: Bách Hóa Xanh | E4: Siêu thị Hải Dương | F4: ST | G4: CHCA | H4: Bia lon Saigon Chill | I4: PK_HPL_LB | J4: HPL Depot Long Biên - 20 Thạch Bàn | K4: Hà Nội | L4: Long Biên | M4: 21.026155 | N4: 105.91418 | O4: DL_HD_SIEUTHI | P4: Siêu thị Hải Dương | Q4: Hải Phòng | R4: Hải Dương | S4: 20.937341 | T4: 106.31455 | U4: Đông Bắc | V4: Đông Bắc | W4: 60.9 | X4: 1914 | Y4: 5.15 | Z4: 4 | AA4: 5T | AB4: 8T | AC4: No | AD4: Yes | AE4: No | AF4: No | AG4: Quốc lộ 5, xe 8T vào được | AH4: 08:00 | AI4: 10:30 | AJ4: 10:51 | AK4: 13:51 | AL4: 45 | AM4: 40 | AN4: 35 | AO4: 351 | AP4: 1050000 | AQ4: 150000 | AR4: 0 | AS4: 150000 | AT4: A - SLA chặt | AU4: CR-ĐÔNG-04 | AV4: Hệ thống khách hàng | AW4: S2-C03 | AX4: 5T | AY4: Send to Clustering | AZ4: OK | BA4: OK | BB4: =AM4+AN4 | BC4: =ROUND(W4/'03_Cost_Constraints'!$B$4*60,0) | BD4: =IF(X4<=500,"5 tạ",IF(X4<=1250,"1.25T",IF(X4<=5000,"5T",IF(X4<=8000,"8T",IF(X4<=15000,"3 chân","4 chân"))))) | BE4: =IF((BB4+BC4)<=AO4,"OK","Risk") | BF4: =IF(AND(AZ4="OK",BE4="OK"),"Ready","Review")
A5: S2 | B5: 2026-06-05 | C5: S2-ORD-004 | D5: MM Mega Market | E5: Thái Dương | F5: Đại lý | G5: MILK | H5: Sữa hộp carton | I5: PK_LINFOX_VSIP | J5: Kho Linfox KCN VSIP Bắc Ninh | K5: Bắc Ninh | L5: Từ Sơn | M5: 21.082707 | N5: 105.99795 | O5: DL_HN_THAIDUONG | P5: Thái Dương | Q5: Hà Nội | R5: Hà Nội | S5: 20.929215 | T5: 105.87 | U5: Nội thành Hà Nội | V5: Nội thành Hà Nội | W5: 33.6 | X5: 1286 | Y5: 2.73 | Z5: 2 | AA5: 5T | AB5: 1.25T | AC5: No | AD5: Yes | AE5: No | AF5: Yes | AG5: Đường nhỏ, ưu tiên xe <=1.25T | AH5: 08:00 | AI5: 09:30 | AJ5: 10:57 | AK5: 12:27 | AL5: 30 | AM5: 40 | AN5: 35 | AO5: 267 | AP5: 800000 | AQ5: 0 | AR5: 0 | AS5: 150000 | AT5: A - SLA chặt | AU5: CR-NỘIT-05 | AV5: Zalo/Email plan 17:00 | AW5: S2-C04 | AX5: Split/Chuyển tải | AY5: Split Order/Chuyển tải hoặc xin xe nhỏ nhiều chuyến | AZ5: Review | BA5: Vehicle Mismatch | BB5: =AM5+AN5 | BC5: =ROUND(W5/'03_Cost_Constraints'!$B$4*60,0) | BD5: =IF(X5<=500,"5 tạ",IF(X5<=1250,"1.25T",IF(X5<=5000,"5T",IF(X5<=8000,"8T",IF(X5<=15000,"3 chân","4 chân"))))) | BE5: =IF((BB5+BC5)<=AO5,"OK","Risk") | BF5: =IF(AND(AZ5="OK",BE5="OK"),"Ready","Review") | BG5: Kế hoạch ngày hôm sau; cần chốt trước 19:00 và gửi tài xế sau duyệt
