Workbook

Sheet README
A1: HPL AI Dispatching & Routing Engine - Dynamic Simulation Dataset
A2: Mục đích | B2: Bổ sung dữ liệu động trong ngày vận hành để mô phỏng các sự cố phát sinh sau khi kế hoạch pre-day đã được duyệt.
A3: Phạm vi | B3: 3 case chính: xe hỏng giữa đường; khách đổi khung giờ/đóng hàng muộn; tắc nghẽn giao thông và xe bị kiểm tra dẫn đến trễ SLA.
A4: Nguyên tắc | B4: Không hủy đơn nếu còn phương án xử lý; ưu tiên re-route, điều xe gần nhất, thương lượng khung giờ, xin duyệt cấp trên và kiểm soát chi phí/phạt rỗng.
A5: Luồng xử lý | B5: Detect → Classify → Impact Analysis → Generate Options → Dispatcher Decision → Re-optimize → Notify → Close & Learn.
A6: Logic hệ thống | B6: Tất cả tình huống được thiết kế để phục vụ thuật toán Dynamic Re-routing, Candidate Vehicle Search, Soft Time Window, SLA Penalty và Risk Scoring.
A7: Ghi chú dữ liệu | B7: Dữ liệu là mô phỏng có kiểm soát, bám theo bài toán HPL: xe phân phối, khung giờ, tải trọng/dung tích, điều phối bán kính, tài xế xác nhận và khách hàng xác nhận.
A9: NOTE | B9: Ví dụ bây giờ data động, cần biết thời gian xảy ra.
B10: Tick cột đấy ở data tĩnh => Đơn hàng sẽ track ra 1 sheets khác => Dispatcher sẽ summary lại => Cần thiết kế sao cho có sự liên kết từ các đơn cũ => Tránh thời gian thủ công. Track từ data tĩnh sang sheets của data động.
B11: Từ đây update data => Định tuyến lại hoặc soft skill => Note từ Dispatcher để lưu vết, sau để truy xuất

Sheet Parameters
A1: Parameter | B1: Value | C1: Unit | D1: Purpose
A2: Search_Radius_Min | B2: 2 | C2: km | D2: Bán kính tối thiểu khi quét xe thay thế
A3: Search_Radius_Max | B3: 30 | C3: km | D3: Bán kính tối đa khi quét xe thay thế
A4: Average_Recovery_Speed | B4: 35 | C4: km/h | D4: Tốc độ trung bình để xe thay thế tiếp cận điểm sự cố
A5: Transfer_Service_Time | B5: 20 | C5: minutes | D5: Thời gian chuyển tải/đổi xe tại điểm an toàn
A6: Empty_Run_Cost_Per_Km | B6: 10200 | C6: VND/km | D6: Chi phí/phạt rỗng để đánh giá phương án quay đầu
A7: Late_Penalty_Per_Min | B7: 50000 | C7: VND/min | D7: Phạt trễ SLA mô phỏng
A8: Escalation_Cost_Threshold | B8: 1000000 | C8: VND | D8: Ngưỡng chi phí cần xin duyệt cấp trên
A9: Max_Accepted_Minor_Late | B9: 30 | C9: minutes | D9: Ngưỡng trễ nhẹ có thể thương lượng
A10: Driver_Confirm_Required | B10: YES | C10: text | D10: Mọi re-route phải có xác nhận của tài xế nhận lệnh

Sheet Dynamic_Cases
A1: Case_ID | B1: Case_Name | C1: Event_Time | D1: Phase | E1: Trigger_Source | F1: Route_ID | G1: Primary_Order_ID | H1: Original_Vehicle | I1: Event_Type | J1: Original_TW_Start | K1: Original_TW_End | L1: ETA_No_Action | M1: Revised_ETA_After_Action | N1: Impacted_Orders | O1: Required_Load_Ton | P1: Required_Volume_m3 | Q1: Must_Not_Cancel | R1: Negotiation_Result | S1: Selected_Decision | T1: Delay_Before_Min | U1: Delay_After_Min | V1: SLA_After_Action | W1: Revenue_At_Risk_VND | X1: Additional_Cost_VND | Y1: Empty_KM_Avoided | Z1: Empty_Cost_Avoided_VND | AA1: Profit_Protected_VND | AB1: Resolution_Status | AC1: Residual_Risk | AD1: Core_Rationale
A2: DYN01 | B2: Xe hỏng giữa đường - buộc điều xe gần nhất | C2: 46179.424 | D2: In-Day Dynamic Re-routing | E2: Driver SOS button/GPS stop > 10 phút | F2: HN-ST-02 | G2: ORD-014 | H2: HPL-T005 | I2: Vehicle Breakdown | J2: 46179.5 | K2: 46179.562 | L2: 46179.59 | M2: 46179.556 | N2: ORD-014; ORD-015; ORD-016 | O2: 3.2 | P2: 14 | Q2: YES | R2: Không thương lượng được do kho đã khóa slot nhập hàng 13:30 | S2: Điều xe rỗng gần nhất trong bán kính 2-30km, chuyển tải tại điểm an toàn, gửi lệnh mới cho tài xế và yêu cầu confirm | T2: =MAX(0,ROUND((L2-K2)*1440,0)) -> 40 | U2: =MAX(0,ROUND((M2-K2)*1440,0)) -> 0 | V2: =IF(U2=0,"On-time",IF(U2<=Parameters!$B$9,"Minor late","Late")) -> On-time | W2: 6500000 | X2: 850000 | Y2: 42 | Z2: =Y2*Parameters!$B$6 -> 428400 | AA2: =W2+Z2-X2 -> 6078400 | AB2: Resolved | AC2: Medium | AD2: Không hủy đơn; xe thay thế đủ tải/dung tích và tới kịp trước deadline; chấp nhận tăng chi phí để bảo vệ SLA và doanh thu.
A3: DYN02 | B3: Khách đổi giờ giao + kho đóng hàng muộn | C3: 46179.358 | D3: In-Day Dynamic Re-sequencing | E3: Customer call + warehouse status update | F3: BN-MT-01 | G3: ORD-022 | H3: HPL-T012 | I3: Customer TW Change & Late Loading | J3: 46179.417 | K3: 46179.458 | L3: 46179.483 | M3: 46179.573 | N3: ORD-021; ORD-022; ORD-023; ORD-024 | O3: 2.4 | P3: 9.5 | Q3: YES | R3: Khách đồng ý đổi slot 13:00-14:30 sau khi dispatcher gọi xác nhận và gửi ETA mới | S3: Đổi thứ tự giao: giao ORD-023 trước, giữ xe trên tuyến, cập nhật TW mềm và lưu xác nhận khách hàng | T3: =MAX(0,ROUND((L3-K3)*1440,0)) -> 35 | U3: =MAX(0,ROUND((M3-K3)*1440,0)) -> 165 | V3: =IF(U3=0,"On-time",IF(U3<=Parameters!$B$9,"Minor late","Late")) -> Late | W3: 4200000 | X3: 180000 | Y3: 18 | Z3: =Y3*Parameters!$B$6 -> 183600 | AA3: =W3+Z3-X3 -> 4203600 | AB3: Resolved | AC3: Low | AD3: Thương lượng thành công nên không cần điều xe khác; re-sequence giúp giảm thời gian chờ và vẫn giữ được SLA.
A4: DYN03 | B4: Tắc đường (phổ biến) + xe bị kiểm tra (optional) | C4: 46179.639 | D4: In-Day Dynamic Re-routing | E4: Traffic alert + driver report | F4: HP-HN-04 | G4: ORD-033 | H4: HPL-T018 | I4: Traffic Congestion & Police Check | J4: 46179.708 | K4: 46179.75 | L4: 46179.799 | M4: 46179.747 | N4: ORD-033; ORD-034 | O4: 1.1 | P4: 6.8 | Q4: YES | R4: Khách chỉ chấp nhận trễ tối đa 15 phút; cần có xác nhận cấp trên cho chi phí chuyển tải | S4: Tách 2 điểm nội thành sang xe 1.25T gần nhất, xe lớn dừng tại điểm trung chuyển ngoài vành đai, cập nhật ETA cho khách | T4: =MAX(0,ROUND((L4-K4)*1440,0)) -> 70 | U4: =MAX(0,ROUND((M4-K4)*1440,0)) -> 0 | V4: =IF(U4=0,"On-time",IF(U4<=Parameters!$B$9,"Minor late","Late")) -> On-time | W4: 5200000 | X4: 1250000 | Y4: 65 | Z4: =Y4*Parameters!$B$6 -> 663000 | AA4: =W4+Z4-X4 -> 4613000 | AB4: Resolved | AC4: Medium-High | AD4: Phương án tuân thủ cấm tải, giảm trễ SLA, nhưng có rủi ro chi phí chuyển tải và cần kiểm soát xác nhận tài xế/khách.
B6: Đến nhưng phải chờ, phát sinh chờ giờ | C6: Kho đóng hàng muộn
C7: Ràng buộc: nếu như trên 1 tiếng thì ntn, dưới 1 tiếng thì ntn
B8: Giao nhầm điểm
B9: Phát sinh đơn mới vào sáng hôm sau | C9: Điều xe trống | D9: ...

Sheet Vehicles_Live_40
A1: Vehicle_ID | B1: Plate_No | C1: Vehicle_Type | D1: Max_Ton | E1: Max_m3 | F1: Driver | G1: Phone | H1: Home_Depot | I1: Region_Profile | J1: Shift_Start | K1: Shift_End | L1: Current_Status | M1: Current_Location | N1: Lat | O1: Lon | P1: Current_Route | Q1: Remaining_Capacity_Ton | R1: Remaining_Volume_m3 | S1: Remaining_Stops | T1: Current_Load_Ton | U1: GPS_Last_Update | V1: Can_Reroute | W1: Maintenance_Risk | X1: Driver_Time_Risk | Y1: Notes
A2: HPL-T001 | B2: 30C-101.07 | C2: 1.25T | D2: 1.25 | E2: 8 | F2: Tài xế 01 | G2: 0910000001 | H2: Long Bien Depot | I2: Ngoai thanh HN | J2: 46179.25 | K2: 46179.75 | L2: In Execution | M2: Bac Ninh ICD | N2: 21.186 | O2: 106.076 | P2: HN-ST-02 | Q2: 0.44 | R2: 2.4 | S2: 2 | T2: 0.81 | U2: 46179.46 | V2: NO | W2: Low | X2: Normal
A3: HPL-T002 | B3: 31C-102.14 | C3: 5T | D3: 5 | E3: 22 | F3: Tài xế 02 | G3: 0910000002 | H3: Long Bien Depot | I3: Dong Bac | J3: 46179.25 | K3: 46179.75 | L3: In Execution | M3: Hai Duong QL5 | N3: 20.938 | O3: 106.316 | P3: HN-ST-03 | Q3: 1.75 | R3: 6.6 | S3: 3 | T3: 3.25 | U3: 46179.504 | V3: NO | W3: Low | X3: Normal
A4: HPL-T003 | B4: 32C-103.21 | C4: 8T | D4: 8 | E4: 35 | F4: Tài xế 03 | G4: 0910000003 | H4: Long Bien Depot | I4: Tay Bac | J4: 46179.25 | K4: 46179.75 | L4: Available | M4: Hai Phong Port | N4: 20.844 | O4: 106.688 | Q4: 6 | R4: 25.2 | S4: 0 | T4: 2 | U4: 46179.548 | V4: YES | W4: Low | X4: Normal
A5: HPL-T004 | B5: 33C-104.28 | C5: 3-chan | D5: 15 | E5: 55 | F5: Tài xế 04 | G5: 0910000004 | H5: Long Bien Depot | I5: Hai Phong - Bac Ninh | J5: 46179.25 | K5: 46179.75 | L5: In Execution | M5: Soc Son | N5: 21.257 | O5: 105.849 | P5: HN-ST-05 | Q5: 5.25 | R5: 16.5 | S5: 1 | T5: 9.75 | U5: 46179.592 | V5: NO | W5: Low | X5: Normal
A6: HPL-T005 | B6: 29C-105.35 | C6: 4-chan | D6: 18 | E6: 65 | F6: Tài xế 05 | G6: 0910000005 | H6: Long Bien Depot | I6: Thanh Hoa - Nghe An | J6: 46179.25 | K6: 46179.75 | L6: Breakdown | M6: Km24 Dai lo Thang Long | N6: 21.005 | O6: 105.6 | P6: HN-ST-01 | Q6: 6.3 | R6: 19.5 | S6: 2 | T6: 11.7 | U6: 46179.635 | V6: NO | W6: High | X6: Normal | Y6: Impacted vehicle
A7: HPL-T006 | B7: 30C-106.42 | C7: 5-ta | D7: 0.5 | E7: 3.5 | F7: Tài xế 06 | G7: 0910000006 | H7: Long Bien Depot | I7: Da Nang | J7: 46179.25 | K7: 46179.75 | L7: Standby | M7: Ha Dong | N7: 20.971 | O7: 105.778 | Q7: 0.38 | R7: 2.5 | S7: 0 | T7: 0.12 | U7: 46179.429 | V7: YES | W7: Low | X7: Normal
A8: HPL-T007 | B8: 31C-107.49 | C8: 1.25T | D8: 1.25 | E8: 8 | F8: Tài xế 07 | G8: 0910000007 | H8: Long Bien Depot | I8: HCM | J8: 46179.25 | K8: 46179.75 | L8: In Execution | M8: Thanh Hoa DC | N8: 19.807 | O8: 105.776 | P8: HN-ST-03 | Q8: 0.44 | R8: 2.4 | S8: 4 | T8: 0.81 | U8: 46179.473 | V8: NO | W8: Low | X8: Normal
A9: HPL-T008 | B9: 32C-108.56 | C9: 5T | D9: 5 | E9: 22 | F9: Tài xế 08 | G9: 0910000008 | H9: Long Bien Depot | I9: Noi thanh HN | J9: 46179.25 | K9: 46179.75 | L9: In Execution | M9: Pho Noi | N9: 20.94 | O9: 106.04 | P9: HN-ST-04 | Q9: 1.75 | R9: 6.6 | S9: 1 | T9: 3.25 | U9: 46179.517 | V9: NO | W9: Low | X9: Normal
A10: HPL-T009 | B10: 33C-109.63 | C10: 8T | D10: 8 | E10: 35 | F10: Tài xế 09 | G10: 0910000009 | H10: Long Bien Depot | I10: Ngoai thanh HN | J10: 46179.25 | K10: 46179.75 | L10: Standby | M10: Gia Lam | N10: 21.034 | O10: 105.935 | Q10: 6 | R10: 25.2 | S10: 0 | T10: 2 | U10: 46179.56 | V10: YES | W10: Low | X10: Normal
A11: HPL-T010 | B11: 29C-110.70 | C11: 3-chan | D11: 15 | E11: 55 | F11: Tài xế 10 | G11: 0910000010 | H11: Long Bien Depot | I11: Dong Bac | J11: 46179.25 | K11: 46179.75 | L11: In Execution | M11: Cau Giay | N11: 21.033 | O11: 105.79 | P11: HN-ST-01 | Q11: 5.25 | R11: 16.5 | S11: 3 | T11: 9.75 | U11: 46179.604 | V11: NO | W11: Low | X11: Normal
A12: HPL-T011 | B12: 30C-111.77 | C12: 4-chan | D12: 18 | E12: 65 | F12: Tài xế 11 | G12: 0910000011 | H12: Long Bien Depot | I12: Tay Bac | J12: 46179.25 | K12: 46179.75 | L12: Available | M12: Vinh Phuc | N12: 21.308 | O12: 105.604 | Q12: 13.5 | R12: 46.8 | S12: 0 | T12: 4.5 | U12: 46179.648 | V12: YES | W12: Medium | X12: Normal | Y12: Candidate for recovery
A13: HPL-T012 | B13: 31C-112.84 | C13: 5-ta | D13: 0.5 | E13: 3.5 | F13: Tài xế 12 | G13: 0910000012 | H13: Long Bien Depot | I13: Hai Phong - Bac Ninh | J13: 46179.25 | K13: 46179.75 | L13: In Execution | M13: Bac Ninh Warehouse | N13: 21.188 | O13: 106.078 | P13: HN-ST-03 | Q13: 0.17 | R13: 1.1 | S13: 1 | T13: 0.33 | U13: 46179.442 | V13: NO | W13: Low | X13: Normal | Y13: Impacted vehicle
A14: HPL-T013 | B14: 32C-113.91 | C14: 1.25T | D14: 1.25 | E14: 8 | F14: Tài xế 13 | G14: 0910000013 | H14: Long Bien Depot | I14: Thanh Hoa - Nghe An | J14: 46179.25 | K14: 46179.75 | L14: In Execution | M14: Bac Ninh ICD | N14: 21.186 | O14: 106.076 | P14: HN-ST-04 | Q14: 0.44 | R14: 2.4 | S14: 2 | T14: 0.81 | U14: 46179.485 | V14: NO | W14: Low | X14: Normal
A15: HPL-T014 | B15: 33C-114.98 | C15: 5T | D15: 5 | E15: 22 | F15: Tài xế 14 | G15: 0910000014 | H15: Long Bien Depot | I15: Da Nang | J15: 46179.25 | K15: 46179.75 | L15: In Execution | M15: Hai Duong QL5 | N15: 20.938 | O15: 106.316 | P15: HN-ST-05 | Q15: 1.75 | R15: 6.6 | S15: 3 | T15: 3.25 | U15: 46179.529 | V15: NO | W15: Low | X15: Normal
A16: HPL-T015 | B16: 29C-115.05 | C16: 8T | D16: 8 | E16: 35 | F16: Tài xế 15 | G16: 0910000015 | H16: Long Bien Depot | I16: HCM | J16: 46179.25 | K16: 46179.75 | L16: Standby | M16: Hai Phong Port | N16: 20.844 | O16: 106.688 | Q16: 6 | R16: 25.2 | S16: 0 | T16: 2 | U16: 46179.573 | V16: YES | W16: Low | X16: Normal
A17: HPL-T016 | B17: 30C-116.12 | C17: 3-chan | D17: 15 | E17: 55 | F17: Tài xế 16 | G17: 0910000016 | H17: Long Bien Depot | I17: Noi thanh HN | J17: 46179.25 | K17: 46179.75 | L17: In Execution | M17: Soc Son | N17: 21.257 | O17: 105.849 | P17: HN-ST-02 | Q17: 5.25 | R17: 16.5 | S17: 1 | T17: 9.75 | U17: 46179.617 | V17: NO | W17: Low | X17: Normal
A18: HPL-T017 | B18: 31C-117.19 | C18: 4-chan | D18: 18 | E18: 65 | F18: Tài xế 17 | G18: 0910000017 | H18: Long Bien Depot | I18: Ngoai thanh HN | J18: 46179.25 | K18: 46179.75 | L18: In Execution | M18: Hoa Lac | N18: 21.013 | O18: 105.526 | P18: HN-ST-03 | Q18: 6.3 | R18: 19.5 | S18: 2 | T18: 11.7 | U18: 46179.66 | V18: NO | W18: Low | X18: Normal
A19: HPL-T018 | B19: 32C-118.26 | C19: 5-ta | D19: 0.5 | E19: 3.5 | F19: Tài xế 18 | G19: 0910000018 | H19: Long Bien Depot | I19: Dong Bac | J19: 46179.25 | K19: 46179.75 | L19: Available | M19: Phu Ly | N19: 20.545 | O19: 105.914 | Q19: 0.38 | R19: 2.5 | S19: 0 | T19: 0.12 | U19: 46179.454 | V19: YES | W19: Low | X19: Near shift end | Y19: Candidate for recovery
A20: HPL-T019 | B20: 33C-119.33 | C20: 1.25T | D20: 1.25 | E20: 8 | F20: Tài xế 19 | G20: 0910000019 | H20: Long Bien Depot | I20: Tay Bac | J20: 46179.25 | K20: 46179.75 | L20: In Execution | M20: Thanh Hoa DC | N20: 19.807 | O20: 105.776 | P20: HN-ST-05 | Q20: 0.44 | R20: 2.4 | S20: 4 | T20: 0.81 | U20: 46179.498 | V20: NO | W20: Low | X20: Normal
A21: HPL-T020 | B21: 29C-120.40 | C21: 5T | D21: 5 | E21: 22 | F21: Tài xế 20 | G21: 0910000020 | H21: Long Bien Depot | I21: Hai Phong - Bac Ninh | J21: 46179.25 | K21: 46179.75 | L21: In Execution | M21: Pho Noi | N21: 20.94 | O21: 106.04 | P21: HN-ST-01 | Q21: 1.75 | R21: 6.6 | S21: 1 | T21: 3.25 | U21: 46179.5 | V21: NO | W21: Low | X21: Normal
A22: HPL-T021 | B22: 30C-121.47 | C22: 8T | D22: 8 | E22: 35 | F22: Tài xế 21 | G22: 0910000021 | H22: Long Bien Depot | I22: Thanh Hoa - Nghe An | J22: 46179.25 | K22: 46179.75 | L22: Standby | M22: Gia Lam | N22: 21.034 | O22: 105.935 | Q22: 6 | R22: 25.2 | S22: 0 | T22: 2 | U22: 46179.544 | V22: YES | W22: Low | X22: Normal
A23: HPL-T022 | B23: 31C-122.54 | C23: 3-chan | D23: 15 | E23: 55 | F23: Tài xế 22 | G23: 0910000022 | H23: Long Bien Depot | I23: Da Nang | J23: 46179.25 | K23: 46179.75 | L23: In Execution | M23: Cau Giay | N23: 21.033 | O23: 105.79 | P23: HN-ST-03 | Q23: 5.25 | R23: 16.5 | S23: 3 | T23: 9.75 | U23: 46179.588 | V23: NO | W23: Medium | X23: Normal
A24: HPL-T023 | B24: 32C-123.61 | C24: 4-chan | D24: 18 | E24: 65 | F24: Tài xế 23 | G24: 0910000023 | H24: Long Bien Depot | I24: HCM | J24: 46179.25 | K24: 46179.75 | L24: In Execution | M24: Vinh Phuc | N24: 21.308 | O24: 105.604 | P24: HN-ST-04 | Q24: 6.3 | R24: 19.5 | S24: 4 | T24: 11.7 | U24: 46179.631 | V24: NO | W24: Low | X24: Normal
A25: HPL-T024 | B25: 33C-124.68 | C25: 5-ta | D25: 0.5 | E25: 3.5 | F25: Tài xế 24 | G25: 0910000024 | H25: Long Bien Depot | I25: Noi thanh HN | J25: 46179.25 | K25: 46179.75 | L25: Available | M25: Long Bien Depot | N25: 21.047 | O25: 105.891 | Q25: 0.38 | R25: 2.5 | S25: 0 | T25: 0.12 | U25: 46179.425 | V25: YES | W25: Low | X25: Normal
A26: HPL-T025 | B26: 29C-125.75 | C26: 1.25T | D26: 1.25 | E26: 8 | F26: Tài xế 25 | G26: 0910000025 | H26: Long Bien Depot | I26: Ngoai thanh HN | J26: 46179.25 | K26: 46179.75 | L26: In Execution | M26: Bac Ninh ICD | N26: 21.186 | O26: 106.076 | P26: HN-ST-01 | Q26: 0.44 | R26: 2.4 | S26: 2 | T26: 0.81 | U26: 46179.469 | V26: NO | W26: Low | X26: Normal
A27: HPL-T026 | B27: 30C-126.82 | C27: 5T | D27: 5 | E27: 22 | F27: Tài xế 26 | G27: 0910000026 | H27: Long Bien Depot | I27: Dong Bac | J27: 46179.25 | K27: 46179.75 | L27: In Execution | M27: Hai Duong QL5 | N27: 20.938 | O27: 106.316 | P27: HN-ST-02 | Q27: 1.75 | R27: 6.6 | S27: 3 | T27: 3.25 | U27: 46179.512 | V27: NO | W27: Low | X27: Normal
A28: HPL-T027 | B28: 31C-127.89 | C28: 8T | D28: 8 | E28: 35 | F28: Tài xế 27 | G28: 0910000027 | H28: Long Bien Depot | I28: Tay Bac | J28: 46179.25 | K28: 46179.75 | L28: Standby | M28: Hai Phong Port | N28: 20.844 | O28: 106.688 | Q28: 6 | R28: 25.2 | S28: 0 | T28: 2 | U28: 46179.556 | V28: YES | W28: Low | X28: Near shift end
A29: HPL-T028 | B29: 32C-128.96 | C29: 3-chan | D29: 15 | E29: 55 | F29: Tài xế 28 | G29: 0910000028 | H29: Long Bien Depot | I29: Hai Phong - Bac Ninh | J29: 46179.25 | K29: 46179.75 | L29: In Execution | M29: Soc Son | N29: 21.257 | O29: 105.849 | P29: HN-ST-04 | Q29: 5.25 | R29: 16.5 | S29: 1 | T29: 9.75 | U29: 46179.6 | V29: NO | W29: Low | X29: Normal
A30: HPL-T029 | B30: 33C-129.03 | C30: 4-chan | D30: 18 | E30: 65 | F30: Tài xế 29 | G30: 0910000029 | H30: Long Bien Depot | I30: Thanh Hoa - Nghe An | J30: 46179.25 | K30: 46179.75 | L30: In Execution | M30: Hoa Lac | N30: 21.013 | O30: 105.526 | P30: HN-ST-05 | Q30: 6.3 | R30: 19.5 | S30: 2 | T30: 11.7 | U30: 46179.644 | V30: NO | W30: Low | X30: Normal
A31: HPL-T030 | B31: 29C-130.10 | C31: 5-ta | D31: 0.5 | E31: 3.5 | F31: Tài xế 30 | G31: 0910000030 | H31: Ha Dong Depot | I31: Da Nang | J31: 46179.25 | K31: 46179.75 | L31: Standby | M31: Ha Dong | N31: 20.971 | O31: 105.778 | Q31: 0.38 | R31: 2.5 | S31: 0 | T31: 0.12 | U31: 46179.438 | V31: YES | W31: Low | X31: Normal
A32: HPL-T031 | B32: 30C-131.17 | C32: 1.25T | D32: 1.25 | E32: 8 | F32: Tài xế 31 | G32: 0910000031 | H32: Ha Dong Depot | I32: HCM | J32: 46179.25 | K32: 46179.75 | L32: In Execution | M32: Thanh Hoa DC | N32: 19.807 | O32: 105.776 | P32: HN-ST-02 | Q32: 0.44 | R32: 2.4 | S32: 4 | T32: 0.81 | U32: 46179.481 | V32: NO | W32: Low | X32: Normal
A33: HPL-T032 | B33: 31C-132.24 | C33: 5T | D33: 5 | E33: 22 | F33: Tài xế 32 | G33: 0910000032 | H33: Ha Dong Depot | I33: Noi thanh HN | J33: 46179.25 | K33: 46179.75 | L33: In Execution | M33: Pho Noi | N33: 20.94 | O33: 106.04 | P33: HN-ST-03 | Q33: 1.75 | R33: 6.6 | S33: 1 | T33: 3.25 | U33: 46179.525 | V33: NO | W33: Low | X33: Normal
A34: HPL-T033 | B34: 32C-133.31 | C34: 8T | D34: 8 | E34: 35 | F34: Tài xế 33 | G34: 0910000033 | H34: Ha Dong Depot | I34: Ngoai thanh HN | J34: 46179.25 | K34: 46179.75 | L34: Available | M34: Yen Nghia | N34: 20.954 | O34: 105.747 | Q34: 6 | R34: 25.2 | S34: 0 | T34: 2 | U34: 46179.569 | V34: YES | W34: Medium | X34: Normal | Y34: Candidate for recovery
A35: HPL-T034 | B35: 33C-134.38 | C35: 3-chan | D35: 15 | E35: 55 | F35: Tài xế 34 | G35: 0910000034 | H35: Ha Dong Depot | I35: Dong Bac | J35: 46179.25 | K35: 46179.75 | L35: In Execution | M35: Cau Giay | N35: 21.033 | O35: 105.79 | P35: HN-ST-05 | Q35: 5.25 | R35: 16.5 | S35: 3 | T35: 9.75 | U35: 46179.613 | V35: NO | W35: Low | X35: Normal
A36: HPL-T035 | B36: 29C-135.45 | C36: 4-chan | D36: 18 | E36: 65 | F36: Tài xế 35 | G36: 0910000035 | H36: Ha Dong Depot | I36: Tay Bac | J36: 46179.25 | K36: 46179.75 | L36: In Execution | M36: Vinh Phuc | N36: 21.308 | O36: 105.604 | P36: HN-ST-01 | Q36: 6.3 | R36: 19.5 | S36: 4 | T36: 11.7 | U36: 46179.656 | V36: NO | W36: Low | X36: Normal
A37: HPL-T036 | B37: 30C-136.52 | C37: 5-ta | D37: 0.5 | E37: 3.5 | F37: Tài xế 36 | G37: 0910000036 | H37: Ha Dong Depot | I37: Hai Phong - Bac Ninh | J37: 46179.25 | K37: 46179.75 | L37: Standby | M37: Long Bien Depot | N37: 21.047 | O37: 105.891 | Q37: 0.38 | R37: 2.5 | S37: 0 | T37: 0.12 | U37: 46179.45 | V37: YES | W37: Low | X37: Normal
A38: HPL-T037 | B38: 31C-137.59 | C38: 1.25T | D38: 1.25 | E38: 8 | F38: Tài xế 37 | G38: 0910000037 | H38: Ha Dong Depot | I38: Thanh Hoa - Nghe An | J38: 46179.25 | K38: 46179.75 | L38: Available | M38: Bac Ninh ICD | N38: 21.186 | O38: 106.076 | Q38: 0.94 | R38: 5.8 | S38: 0 | T38: 0.31 | U38: 46179.494 | V38: YES | W38: Low | X38: Normal
A39: HPL-T038 | B39: 32C-138.66 | C39: 5T | D39: 5 | E39: 22 | F39: Tài xế 38 | G39: 0910000038 | H39: Ha Dong Depot | I39: Da Nang | J39: 46179.25 | K39: 46179.75 | L39: In Execution | M39: Hai Duong QL5 | N39: 20.938 | O39: 106.316 | P39: HN-ST-04 | Q39: 1.75 | R39: 6.6 | S39: 3 | T39: 3.25 | U39: 46179.537 | V39: NO | W39: Low | X39: Normal
A40: HPL-T039 | B40: 33C-139.73 | C40: 8T | D40: 8 | E40: 35 | F40: Tài xế 39 | G40: 0910000039 | H40: Ha Dong Depot | I40: HCM | J40: 46179.25 | K40: 46179.75 | L40: Standby | M40: Hai Phong Port | N40: 20.844 | O40: 106.688 | Q40: 6 | R40: 25.2 | S40: 0 | T40: 2 | U40: 46179.581 | V40: YES | W40: Low | X40: Normal
...

Sheet Orders_Live
A1: Order_ID | B1: Case_ID | C1: Customer | D1: Channel | E1: Pickup_Point | F1: Delivery_Point | G1: Required_Vehicle_Type | H1: Weight_Ton | I1: Volume_m3 | J1: Original_Pickup_TW_Start | K1: Original_Pickup_TW_End | L1: Original_Delivery_TW_Start | M1: Original_Delivery_TW_End | N1: Current_Pickup_TW_Start | O1: Current_Pickup_TW_End | P1: Current_Delivery_TW_Start | Q1: Current_Delivery_TW_End | R1: Original_Vehicle | S1: Current_Assigned_Vehicle | T1: ETA_No_Action | U1: ETA_After_Action | V1: Delay_No_Action_Min | W1: Delay_After_Action_Min | X1: SLA_Status | Y1: Customer_Confirmation | Z1: Driver_Confirmation | AA1: Dispatch_Action | AB1: Risk_Note
A2: ORD-014 | B2: DYN01 | C2: WinMart Cầu Giấy | D2: MT | E2: Kho Hòa Lạc | F2: WinMart Cầu Giấy | G2: 5T | H2: 1.2 | I2: 5.5 | J2: 46179.292 | K2: 46179.333 | L2: 46179.5 | M2: 46179.562 | N2: 46179.292 | O2: 46179.333 | P2: 46179.5 | Q2: 46179.562 | R2: HPL-T005 | S2: HPL-T011 | T2: 46179.59 | U2: 46179.556 | V2: =MAX(0,ROUND((T2-Q2)*1440,0)) -> 40 | W2: =MAX(0,ROUND((U2-Q2)*1440,0)) -> 0 | X2: =IF(W2=0,"On-time",IF(W2<=Parameters!$B$9,"Minor late","Late")) -> On-time | Y2: NO - slot fixed | Z2: PENDING | AA2: Emergency transfer & reassign | AB2: Kho không nhận sau 13:30
A3: ORD-015 | B3: DYN01 | C3: Đại lý Phú Đô | D3: GT | E3: Kho Hòa Lạc | F3: Phú Đô | G3: 5T | H3: 1 | I3: 4.5 | J3: 46179.292 | K3: 46179.333 | L3: 46179.521 | M3: 46179.583 | N3: 46179.292 | O3: 46179.333 | P3: 46179.521 | Q3: 46179.583 | R3: HPL-T005 | S3: HPL-T011 | T3: 46179.608 | U3: 46179.573 | V3: =MAX(0,ROUND((T3-Q3)*1440,0)) -> 35 | W3: =MAX(0,ROUND((U3-Q3)*1440,0)) -> 0 | X3: =IF(W3=0,"On-time",IF(W3<=Parameters!$B$9,"Minor late","Late")) -> On-time | Y3: YES - informed | Z3: PENDING | AA3: Emergency transfer & reassign | AB3: Trễ nhẹ có thể chấp nhận
A4: ORD-016 | B4: DYN01 | C4: Đại lý Mỹ Đình | D4: GT | E4: Kho Hòa Lạc | F4: Mỹ Đình | G4: 5T | H4: 1 | I4: 4 | J4: 46179.292 | K4: 46179.333 | L4: 46179.542 | M4: 46179.625 | N4: 46179.292 | O4: 46179.333 | P4: 46179.542 | Q4: 46179.625 | R4: HPL-T005 | S4: HPL-T011 | T4: 46179.628 | U4: 46179.597 | V4: =MAX(0,ROUND((T4-Q4)*1440,0)) -> 5 | W4: =MAX(0,ROUND((U4-Q4)*1440,0)) -> 0 | X4: =IF(W4=0,"On-time",IF(W4<=Parameters!$B$9,"Minor late","Late")) -> On-time | Y4: YES - informed | Z4: PENDING | AA4: Emergency transfer & reassign | AB4: Không ưu tiên bằng ORD-014
A5: ORD-021 | B5: DYN02 | C5: Masan Bắc Ninh | D5: Distributor | E5: Masan BN Warehouse | F5: Đại lý Tiên Du | G5: 5T | H5: 0.7 | I5: 3 | J5: 46179.333 | K5: 46179.375 | L5: 46179.396 | M5: 46179.438 | N5: 46179.365 | O5: 46179.406 | P5: 46179.396 | Q5: 46179.438 | R5: HPL-T012 | S5: HPL-T012 | T5: 46179.427 | U5: 46179.431 | V5: =MAX(0,ROUND((T5-Q5)*1440,0)) -> 0 | W5: =MAX(0,ROUND((U5-Q5)*1440,0)) -> 0 | X5: =IF(W5=0,"On-time",IF(W5<=Parameters!$B$9,"Minor late","Late")) -> On-time | Y5: YES | Z5: YES | AA5: Keep route | AB5: Kho đóng hàng muộn 45 phút
A6: ORD-022 | B6: DYN02 | C6: Masan Bắc Ninh | D6: MT | E6: Masan BN Warehouse | F6: Siêu thị Từ Sơn | G6: 5T | H6: 0.8 | I6: 3.2 | J6: 46179.333 | K6: 46179.375 | L6: 46179.417 | M6: 46179.458 | N6: 46179.365 | O6: 46179.406 | P6: 46179.542 | Q6: 46179.604 | R6: HPL-T012 | S6: HPL-T012 | T6: 46179.483 | U6: 46179.573 | V6: =MAX(0,ROUND((T6-Q6)*1440,0)) -> 0 | W6: =MAX(0,ROUND((U6-Q6)*1440,0)) -> 0 | X6: =IF(W6=0,"On-time",IF(W6<=Parameters!$B$9,"Minor late","Late")) -> On-time | Y6: YES - new slot confirmed | Z6: YES | AA6: Resequence after ORD-023 | AB6: Khách chủ động đổi giờ
A7: ORD-023 | B7: DYN02 | C7: Masan Bắc Ninh | D7: GT | E7: Masan BN Warehouse | F7: Đại lý Yên Phong | G7: 5T | H7: 0.5 | I7: 1.8 | J7: 46179.333 | K7: 46179.375 | L7: 46179.458 | M7: 46179.5 | N7: 46179.365 | O7: 46179.406 | P7: 46179.458 | Q7: 46179.5 | R7: HPL-T012 | S7: HPL-T012 | T7: 46179.476 | U7: 46179.486 | V7: =MAX(0,ROUND((T7-Q7)*1440,0)) -> 0 | W7: =MAX(0,ROUND((U7-Q7)*1440,0)) -> 0 | X7: =IF(W7=0,"On-time",IF(W7<=Parameters!$B$9,"Minor late","Late")) -> On-time | Y7: YES | Z7: YES | AA7: Move before ORD-022 | AB7: Dùng để lấp thời gian chờ
A8: ORD-024 | B8: DYN02 | C8: Masan Bắc Ninh | D8: GT | E8: Masan BN Warehouse | F8: Đại lý Bắc Giang | G8: 5T | H8: 0.4 | I8: 1.5 | J8: 46179.333 | K8: 46179.375 | L8: 46179.583 | M8: 46179.625 | N8: 46179.365 | O8: 46179.406 | P8: 46179.583 | Q8: 46179.625 | R8: HPL-T012 | S8: HPL-T012 | T8: 46179.618 | U8: 46179.622 | V8: =MAX(0,ROUND((T8-Q8)*1440,0)) -> 0 | W8: =MAX(0,ROUND((U8-Q8)*1440,0)) -> 0 | X8: =IF(W8=0,"On-time",IF(W8<=Parameters!$B$9,"Minor late","Late")) -> On-time | Y8: YES | Z8: YES | AA8: Keep route | AB8: Không ảnh hưởng
A9: ORD-033 | B9: DYN03 | C9: Siêu thị nội thành Hà Nội | D9: MT | E9: Hải Phòng Port | F9: Cầu Giấy Store | G9: 1.25T required after transshipment | H9: 0.6 | I9: 3.8 | J9: 46179.375 | K9: 46179.417 | L9: 46179.708 | M9: 46179.75 | N9: 46179.375 | O9: 46179.417 | P9: 46179.708 | Q9: 46179.75 | R9: HPL-T018 | S9: HPL-T033 | T9: 46179.799 | U9: 46179.747 | V9: =MAX(0,ROUND((T9-Q9)*1440,0)) -> 70 | W9: =MAX(0,ROUND((U9-Q9)*1440,0)) -> 0 | X9: =IF(W9=0,"On-time",IF(W9<=Parameters!$B$9,"Minor late","Late")) -> On-time | Y9: YES - max +15 min | Z9: PENDING | AA9: Split to 1.25T at ring road | AB9: Cấm tải xe lớn giờ cao điểm
A10: ORD-034 | B10: DYN03 | C10: Đại lý Thanh Xuân | D10: GT | E10: Hải Phòng Port | F10: Thanh Xuân | G10: 1.25T | H10: 0.5 | I10: 3 | J10: 46179.375 | K10: 46179.417 | L10: 46179.729 | M10: 46179.771 | N10: 46179.375 | O10: 46179.417 | P10: 46179.729 | Q10: 46179.771 | R10: HPL-T018 | S10: HPL-T033 | T10: 46179.816 | U10: 46179.757 | V10: =MAX(0,ROUND((T10-Q10)*1440,0)) -> 65 | W10: =MAX(0,ROUND((U10-Q10)*1440,0)) -> 0 | X10: =IF(W10=0,"On-time",IF(W10<=Parameters!$B$9,"Minor late","Late")) -> On-time | Y10: YES - informed | Z10: PENDING | AA10: Split to 1.25T at ring road | AB10: Rủi ro trễ nhẹ

Sheet Replacement_Candidates
A1: Case_ID | B1: Incident_Location | C1: Incident_Lat | D1: Incident_Lon | E1: Candidate_Vehicle | F1: Vehicle_Type | G1: Candidate_Status | H1: Candidate_Lat | I1: Candidate_Lon | J1: Distance_To_Incident_Km | K1: Search_Radius_Km | L1: Within_Radius | M1: Available_Payload_Ton | N1: Required_Payload_Ton | O1: Available_m3 | P1: Required_m3 | Q1: Capacity_OK | R1: ETA_To_Incident_Min | S1: Transfer_Time_Min | T1: Latest_Recovery_Arrival | U1: Recovery_Feasible | V1: Driver_Confirm | W1: Supervisor_Approval | X1: Risk_Deduct | Y1: Candidate_Score | Z1: Recommended | AA1: Reason
A2: DYN01 | B2: Km24 Dai lo Thang Long | C2: 21.005 | D2: 105.6 | E2: HPL-T011 | F2: 5T | G2: Available | H2: 21.013 | I2: 105.526 | J2: =ROUND(SQRT(((H2-C2)*111)^2+((I2-D2)*109)^2),2) -> 8.11 | K2: 30 | L2: =IF(AND(J2>=Parameters!$B$2,J2<=$K2),"YES","NO") -> YES | M2: 3.8 | N2: 3.2 | O2: 16 | P2: 14 | Q2: =IF(AND(M2>=N2,O2>=P2),"YES","NO") -> YES | R2: =ROUND(J2/Parameters!$B$4*60,0) -> 14 | S2: 20 | T2: 46179.531 | U2: =IF(AND(L2="YES",Q2="YES",R2+S2<=120),"YES","CHECK") -> YES | V2: YES | W2: Not required | X2: 8 | Y2: =IF(AND(L2="YES",Q2="YES",U2="YES",V2="YES"),ROUND(100-J2*2+M2*5+O2-X2,1),-999) -> 110.8 | Z2: =IF(Y2=MAXIFS($Y:$Y,$A:$A,A2),"RECOMMENDED","") -> RECOMMENDED | AA2: Gần điểm sự cố nhất, đủ tải/dung tích, tài xế xác nhận nhận chuyến
A3: DYN01 | B3: Km24 Dai lo Thang Long | C3: 21.005 | D3: 105.6 | E3: HPL-T018 | F3: 8T | G3: Available | H3: 20.545 | I3: 105.914 | J3: =ROUND(SQRT(((H3-C3)*111)^2+((I3-D3)*109)^2),2) -> 61.47 | K3: 30 | L3: =IF(AND(J3>=Parameters!$B$2,J3<=$K3),"YES","NO") -> NO | M3: 5 | N3: 3.2 | O3: 20 | P3: 14 | Q3: =IF(AND(M3>=N3,O3>=P3),"YES","NO") -> YES | R3: =ROUND(J3/Parameters!$B$4*60,0) -> 105 | S3: 20 | T3: 46179.531 | U3: =IF(AND(L3="YES",Q3="YES",R3+S3<=120),"YES","CHECK") -> CHECK | V3: YES | W3: Required | X3: 15 | Y3: =IF(AND(L3="YES",Q3="YES",U3="YES",V3="YES"),ROUND(100-J3*2+M3*5+O3-X3,1),-999) -> -999 | Z3: =IF(Y3=MAXIFS($Y:$Y,$A:$A,A3),"RECOMMENDED","") | AA3: Xa hơn, chi phí cao hơn, vẫn khả thi nếu xe HPL-T011 không xác nhận
A4: DYN01 | B4: Km24 Dai lo Thang Long | C4: 21.005 | D4: 105.6 | E4: HPL-T026 | F4: 1.25T | G4: Standby | H4: 20.971 | I4: 105.778 | J4: =ROUND(SQRT(((H4-C4)*111)^2+((I4-D4)*109)^2),2) -> 19.77 | K4: 30 | L4: =IF(AND(J4>=Parameters!$B$2,J4<=$K4),"YES","NO") -> YES | M4: 1 | N4: 3.2 | O4: 6 | P4: 14 | Q4: =IF(AND(M4>=N4,O4>=P4),"YES","NO") -> NO | R4: =ROUND(J4/Parameters!$B$4*60,0) -> 34 | S4: 20 | T4: 46179.531 | U4: =IF(AND(L4="YES",Q4="YES",R4+S4<=120),"YES","CHECK") -> CHECK | V4: YES | W4: Not required | X4: 25 | Y4: =IF(AND(L4="YES",Q4="YES",U4="YES",V4="YES"),ROUND(100-J4*2+M4*5+O4-X4,1),-999) -> -999 | Z4: =IF(Y4=MAXIFS($Y:$Y,$A:$A,A4),"RECOMMENDED","") | AA4: Không đủ tải/dung tích nên loại
A5: DYN01 | B5: Km24 Dai lo Thang Long | C5: 21.005 | D5: 105.6 | E5: HPL-T037 | F5: 5-ta | G5: Available | H5: 21.034 | I5: 105.935 | J5: =ROUND(SQRT(((H5-C5)*111)^2+((I5-D5)*109)^2),2) -> 36.66 | K5: 30 | L5: =IF(AND(J5>=Parameters!$B$2,J5<=$K5),"YES","NO") -> NO | M5: 0.4 | N5: 3.2 | O5: 3 | P5: 14 | Q5: =IF(AND(M5>=N5,O5>=P5),"YES","NO") -> NO | R5: =ROUND(J5/Parameters!$B$4*60,0) -> 63 | S5: 20 | T5: 46179.531 | U5: =IF(AND(L5="YES",Q5="YES",R5+S5<=120),"YES","CHECK") -> CHECK | V5: YES | W5: Not required | X5: 30 | Y5: =IF(AND(L5="YES",Q5="YES",U5="YES",V5="YES"),ROUND(100-J5*2+M5*5+O5-X5,1),-999) -> -999 | Z5: =IF(Y5=MAXIFS($Y:$Y,$A:$A,A5),"RECOMMENDED","") | AA5: Quá nhỏ và không phù hợp chuyển tải
A6: DYN02 | B6: Masan BN Warehouse | C6: 21.188 | D6: 106.078 | E6: HPL-T012 | F6: 5T | G6: In Execution | H6: 21.188 | I6: 106.078 | J6: =ROUND(SQRT(((H6-C6)*111)^2+((I6-D6)*109)^2),2) -> 0 | K6: 30 | L6: =IF(AND(J6>=Parameters!$B$2,J6<=$K6),"YES","NO") -> NO | M6: 2.6 | N6: 2.4 | O6: 12 | P6: 9.5 | Q6: =IF(AND(M6>=N6,O6>=P6),"YES","NO") -> YES | R6: =ROUND(J6/Parameters!$B$4*60,0) -> 0 | S6: 0 | T6: 46179.562 | U6: =IF(AND(L6="YES",Q6="YES",R6+S6<=120),"YES","CHECK") -> CHECK | V6: YES | W6: Not required | X6: 5 | Y6: =IF(AND(L6="YES",Q6="YES",U6="YES",V6="YES"),ROUND(100-J6*2+M6*5+O6-X6,1),-999) -> -999 | Z6: =IF(Y6=MAXIFS($Y:$Y,$A:$A,A6),"RECOMMENDED","") -> RECOMMENDED | AA6: Không cần xe thay thế; chỉ cần đổi thứ tự giao và xác nhận khách
A7: DYN02 | B7: Masan BN Warehouse | C7: 21.188 | D7: 106.078 | E7: HPL-T024 | F7: 8T | G7: Standby | H7: 21.186 | I7: 106.076 | J7: =ROUND(SQRT(((H7-C7)*111)^2+((I7-D7)*109)^2),2) -> 0.31 | K7: 30 | L7: =IF(AND(J7>=Parameters!$B$2,J7<=$K7),"YES","NO") -> NO | M7: 6 | N7: 2.4 | O7: 25 | P7: 9.5 | Q7: =IF(AND(M7>=N7,O7>=P7),"YES","NO") -> YES | R7: =ROUND(J7/Parameters!$B$4*60,0) -> 1 | S7: 20 | T7: 46179.562 | U7: =IF(AND(L7="YES",Q7="YES",R7+S7<=120),"YES","CHECK") -> CHECK | V7: YES | W7: Required | X7: 20 | Y7: =IF(AND(L7="YES",Q7="YES",U7="YES",V7="YES"),ROUND(100-J7*2+M7*5+O7-X7,1),-999) -> -999 | Z7: =IF(Y7=MAXIFS($Y:$Y,$A:$A,A7),"RECOMMENDED","") -> RECOMMENDED | AA7: Xe dự phòng nếu khách đổi slot không thành công
A8: DYN02 | B8: Masan BN Warehouse | C8: 21.188 | D8: 106.078 | E8: HPL-T003 | F8: 1.25T | G8: Available | H8: 21.257 | I8: 105.849 | J8: =ROUND(SQRT(((H8-C8)*111)^2+((I8-D8)*109)^2),2) -> 26.11 | K8: 30 | L8: =IF(AND(J8>=Parameters!$B$2,J8<=$K8),"YES","NO") -> YES | M8: 0.9 | N8: 2.4 | O8: 7 | P8: 9.5 | Q8: =IF(AND(M8>=N8,O8>=P8),"YES","NO") -> NO | R8: =ROUND(J8/Parameters!$B$4*60,0) -> 45 | S8: 20 | T8: 46179.562 | U8: =IF(AND(L8="YES",Q8="YES",R8+S8<=120),"YES","CHECK") -> CHECK | V8: YES | W8: Not required | X8: 30 | Y8: =IF(AND(L8="YES",Q8="YES",U8="YES",V8="YES"),ROUND(100-J8*2+M8*5+O8-X8,1),-999) -> -999 | Z8: =IF(Y8=MAXIFS($Y:$Y,$A:$A,A8),"RECOMMENDED","") -> RECOMMENDED | AA8: Không đủ tải/dung tích toàn cụm, chỉ phù hợp tách đơn nhỏ
A9: DYN03 | B9: Ring road transshipment point | C9: 20.954 | D9: 105.747 | E9: HPL-T033 | F9: 1.25T | G9: Available | H9: 20.954 | I9: 105.747 | J9: =ROUND(SQRT(((H9-C9)*111)^2+((I9-D9)*109)^2),2) -> 0 | K9: 30 | L9: =IF(AND(J9>=Parameters!$B$2,J9<=$K9),"YES","NO") -> NO | M9: 1.1 | N9: 1.1 | O9: 6.8 | P9: 6.8 | Q9: =IF(AND(M9>=N9,O9>=P9),"YES","NO") -> YES | R9: =ROUND(J9/Parameters!$B$4*60,0) -> 0 | S9: 20 | T9: 46179.722 | U9: =IF(AND(L9="YES",Q9="YES",R9+S9<=120),"YES","CHECK") -> CHECK | V9: YES | W9: Required | X9: 8 | Y9: =IF(AND(L9="YES",Q9="YES",U9="YES",V9="YES"),ROUND(100-J9*2+M9*5+O9-X9,1),-999) -> -999 | Z9: =IF(Y9=MAXIFS($Y:$Y,$A:$A,A9),"RECOMMENDED","") -> RECOMMENDED | AA9: Phù hợp cấm tải nội thành, đang gần điểm trung chuyển, được khuyến nghị
A10: DYN03 | B10: Ring road transshipment point | C10: 20.954 | D10: 105.747 | E10: HPL-T018 | F10: 8T | G10: In Execution | H10: 20.545 | I10: 105.914 | J10: =ROUND(SQRT(((H10-C10)*111)^2+((I10-D10)*109)^2),2) -> 48.91 | K10: 30 | L10: =IF(AND(J10>=Parameters!$B$2,J10<=$K10),"YES","NO") -> NO | M10: 5.5 | N10: 1.1 | O10: 20 | P10: 6.8 | Q10: =IF(AND(M10>=N10,O10>=P10),"YES","NO") -> YES | R10: =ROUND(J10/Parameters!$B$4*60,0) -> 84 | S10: 20 | T10: 46179.722 | U10: =IF(AND(L10="YES",Q10="YES",R10+S10<=120),"YES","CHECK") -> CHECK | V10: YES | W10: Required | X10: 40 | Y10: =IF(AND(L10="YES",Q10="YES",U10="YES",V10="YES"),ROUND(100-J10*2+M10*5+O10-X10,1),-999) -> -999 | Z10: =IF(Y10=MAXIFS($Y:$Y,$A:$A,A10),"RECOMMENDED","") -> RECOMMENDED | AA10: Xe gốc bị chậm và không vào nội thành đúng giờ do cấm tải
A11: DYN03 | B11: Ring road transshipment point | C11: 20.954 | D11: 105.747 | E11: HPL-T024 | F11: 8T | G11: Standby | H11: 21.186 | I11: 106.076 | J11: =ROUND(SQRT(((H11-C11)*111)^2+((I11-D11)*109)^2),2) -> 44.15 | K11: 30 | L11: =IF(AND(J11>=Parameters!$B$2,J11<=$K11),"YES","NO") -> NO | M11: 6 | N11: 1.1 | O11: 25 | P11: 6.8 | Q11: =IF(AND(M11>=N11,O11>=P11),"YES","NO") -> YES | R11: =ROUND(J11/Parameters!$B$4*60,0) -> 76 | S11: 20 | T11: 46179.722 | U11: =IF(AND(L11="YES",Q11="YES",R11+S11<=120),"YES","CHECK") -> CHECK | V11: YES | W11: Required | X11: 25 | Y11: =IF(AND(L11="YES",Q11="YES",U11="YES",V11="YES"),ROUND(100-J11*2+M11*5+O11-X11,1),-999) -> -999 | Z11: =IF(Y11=MAXIFS($Y:$Y,$A:$A,A11),"RECOMMENDED","") -> RECOMMENDED | AA11: Đủ tải nhưng xe lớn không phù hợp cấm tải nội thành
A12: DYN03 | B12: Ring road transshipment point | C12: 20.954 | D12: 105.747 | E12: HPL-T003 | F12: 1.25T | G12: Available | H12: 21.257 | I12: 105.849 | J12: =ROUND(SQRT(((H12-C12)*111)^2+((I12-D12)*109)^2),2) -> 35.42 | K12: 30 | L12: =IF(AND(J12>=Parameters!$B$2,J12<=$K12),"YES","NO") -> NO | M12: 0.9 | N12: 1.1 | O12: 7 | P12: 6.8 | Q12: =IF(AND(M12>=N12,O12>=P12),"YES","NO") -> NO | R12: =ROUND(J12/Parameters!$B$4*60,0) -> 61 | S12: 20 | T12: 46179.722 | U12: =IF(AND(L12="YES",Q12="YES",R12+S12<=120),"YES","CHECK") -> CHECK | V12: YES | W12: Not required | X12: 18 | Y12: =IF(AND(L12="YES",Q12="YES",U12="YES",V12="YES"),ROUND(100-J12*2+M12*5+O12-X12,1),-999) -> -999 | Z12: =IF(Y12=MAXIFS($Y:$Y,$A:$A,A12),"RECOMMENDED","") -> RECOMMENDED | AA12: Gần nhưng thiếu tải nhẹ; chỉ dùng nếu tách đơn nhỏ hơn

Sheet Event_Workflow
A1: Case_ID | B1: Step_No | C1: Step_Name | D1: Responsible | E1: System_Action | F1: Human_Action | G1: Output_Data | H1: Decision_Gate | I1: Risk_Control
A2: DYN01 | B2: 1 | C2: Detect | D2: AI Engine + Dispatcher | E2: Ghi nhận timestamp, vị trí, tuyến, xe, đơn bị ảnh hưởng | F2: GPS/tài xế/khách hàng phát hiện bất thường | G2: DYN01_Step_1_Output | H2: Continue | I2: Không được hủy đơn; nếu khách không đồng ý đổi giờ thì bắt buộc điều xe thay thế.
A3: DYN01 | B3: 2 | C3: Classify | D3: AI Engine + Dispatcher | E3: Gán loại sự cố: xe hỏng, đổi TW, đóng hàng muộn, tắc đường, bị kiểm tra | F3: Phân loại sự cố | G3: DYN01_Step_2_Output | H3: Continue | I3: Không được hủy đơn; nếu khách không đồng ý đổi giờ thì bắt buộc điều xe thay thế.
A4: DYN01 | B4: 3 | C4: Impact Analysis | D4: AI Engine + Dispatcher | E4: Tính ETA mới, độ trễ, đơn bị ảnh hưởng, chi phí phát sinh, rủi ro SLA | F4: Tính ảnh hưởng | G4: DYN01_Step_3_Output | H4: Continue | I4: Không được hủy đơn; nếu khách không đồng ý đổi giờ thì bắt buộc điều xe thay thế.
A5: DYN01 | B5: 4 | C5: Generate Options | D5: AI Engine + Dispatcher | E5: Đề xuất re-sequence, điều xe gần nhất, tách điểm, chuyển tải, xin đổi giờ | F5: Sinh phương án xử lý | G5: DYN01_Step_4_Output | H5: Go/No-Go | I5: Không được hủy đơn; nếu khách không đồng ý đổi giờ thì bắt buộc điều xe thay thế.
A6: DYN01 | B6: 5 | C6: Dispatcher Decision | D6: Dispatcher/Driver/CS | E6: So sánh SLA, chi phí, rủi ro, lợi nhuận và xin duyệt nếu cần | F6: Điều phối viên chọn phương án | G6: DYN01_Step_5_Output | H6: Go/No-Go | I6: Không được hủy đơn; nếu khách không đồng ý đổi giờ thì bắt buộc điều xe thay thế.
A7: DYN01 | B7: 6 | C7: Re-optimize | D7: Dispatcher/Driver/CS | E7: Tạo tuyến mới, ETA mới, danh sách tài xế/xe thay thế | F7: Chạy lại tuyến phần bị ảnh hưởng | G7: DYN01_Step_6_Output | H7: Continue | I7: Không được hủy đơn; nếu khách không đồng ý đổi giờ thì bắt buộc điều xe thay thế.
A8: DYN01 | B8: 7 | C8: Notify | D8: Dispatcher/Driver/CS | E8: Gửi lệnh tài xế, gọi khách/kho, gửi ETA mới, lưu xác nhận | F8: Thông báo các bên | G8: DYN01_Step_7_Output | H8: Continue | I8: Không được hủy đơn; nếu khách không đồng ý đổi giờ thì bắt buộc điều xe thay thế.
A9: DYN01 | B9: 8 | C9: Close & Learn | D9: Dispatcher/Driver/CS | E9: Ghi nhận nguyên nhân, thời gian xử lý, chi phí, bài học cho mô hình | F9: Đóng sự cố và học lại | G9: DYN01_Step_8_Output | H9: Continue | I9: Không được hủy đơn; nếu khách không đồng ý đổi giờ thì bắt buộc điều xe thay thế.
A10: DYN02 | B10: 1 | C10: Detect | D10: AI Engine + Dispatcher | E10: Ghi nhận timestamp, vị trí, tuyến, xe, đơn bị ảnh hưởng | F10: GPS/tài xế/khách hàng phát hiện bất thường | G10: DYN02_Step_1_Output | H10: Continue | I10: Cần có xác nhận khách hàng trước khi cập nhật khung giờ mềm.
A11: DYN02 | B11: 2 | C11: Classify | D11: AI Engine + Dispatcher | E11: Gán loại sự cố: xe hỏng, đổi TW, đóng hàng muộn, tắc đường, bị kiểm tra | F11: Phân loại sự cố | G11: DYN02_Step_2_Output | H11: Continue | I11: Cần có xác nhận khách hàng trước khi cập nhật khung giờ mềm.
A12: DYN02 | B12: 3 | C12: Impact Analysis | D12: AI Engine + Dispatcher | E12: Tính ETA mới, độ trễ, đơn bị ảnh hưởng, chi phí phát sinh, rủi ro SLA | F12: Tính ảnh hưởng | G12: DYN02_Step_3_Output | H12: Continue | I12: Cần có xác nhận khách hàng trước khi cập nhật khung giờ mềm.
A13: DYN02 | B13: 4 | C13: Generate Options | D13: AI Engine + Dispatcher | E13: Đề xuất re-sequence, điều xe gần nhất, tách điểm, chuyển tải, xin đổi giờ | F13: Sinh phương án xử lý | G13: DYN02_Step_4_Output | H13: Go/No-Go | I13: Cần có xác nhận khách hàng trước khi cập nhật khung giờ mềm.
... A25: DYN03 | B25: 8 | C25: Close & Learn | D25: Dispatcher/Driver/CS | E25: Ghi nhận nguyên nhân, thời gian xử lý, chi phí, bài học cho mô hình | F25: Đóng sự cố và học lại | G25: DYN03_Step_8_Output | H25: Continue | I25: Phải tuân thủ cấm tải; mọi chi phí chuyển tải vượt ngưỡng cần xin cấp trên.

Sheet Soft_Skill_Playbook
A1: Case_ID | B1: Situation | C1: Soft_Skill_Action | D1: Suggested_Script | E1: Owner | F1: Escalation_Condition | G1: Evidence_To_Save
A2: DYN01 | B2: Xe hỏng và khách không cho đổi giờ | C2: Gọi khách/kho ngay để thông báo sự cố trung thực, xin giữ slot nhập hàng, cam kết xe thay thế đang đến | D2: Dạ anh/chị, xe đang gặp sự cố kỹ thuật trên đường. Bên em đã kích hoạt xe thay thế gần nhất và dự kiến vẫn đến trong khung giờ. Mong anh/chị hỗ trợ giữ slot để bên em không ảnh hưởng kế hoạch nhập kho của mình ạ. | E2: Dispatcher + CS | F2: Nếu revised ETA vẫn sau TW end hoặc phát sinh chi phí chuyển tải > ngưỡng | G2: Call log, ETA mới, xác nhận tài xế nhận lệnh, ảnh sự cố nếu có
A3: DYN01 | B3: Cần xe thay thế | C3: Gọi tài xế ứng viên, nói rõ địa điểm, tải còn lại, điểm giao và yêu cầu xác nhận nhận chuyến | D3: Anh ơi hệ thống đang điều anh hỗ trợ sự cố tuyến HN-ST-02. Anh xác nhận giúp em khả năng nhận 3.2 tấn/14 m3 và tới điểm chuyển tải trước 10:45 được không ạ? | E3: Dispatcher | F3: Nếu tài xế không xác nhận trong 3 phút, chuyển sang ứng viên thứ hai | G3: Driver confirmation timestamp
A4: DYN02 | B4: Khách đổi giờ giao | C4: Không tranh luận; xác nhận lại khung giờ mới, xin văn bản/Zalo xác nhận để cập nhật hệ thống | D4: Dạ em xác nhận lại: đơn ORD-022 sẽ chuyển slot nhận sang 13:00-14:30. Bên em sẽ điều chỉnh thứ tự giao và gửi lại ETA trước khi xe đến ạ. | E4: CS/Dispatcher | F4: Nếu thay đổi làm trễ các đơn sau hoặc phát sinh phí chờ | G4: Customer confirmation, new TW
A5: DYN02 | B5: Kho đóng hàng muộn | C5: Gọi kho để xác định giờ hàng sẵn sàng thật, tránh xe chờ vô ích | D5: Dạ bên em cần xác nhận hàng có thể bốc lúc mấy giờ để điều phối lại tuyến, tránh xe vào sớm rồi chờ lâu và ảnh hưởng các điểm sau ạ. | E5: Dispatcher | F5: Nếu chờ > thời gian miễn phí hoặc ảnh hưởng đơn SLA cao | G5: Warehouse confirmation, wait reason
A6: DYN03 | B6: Tắc đường/xe bị kiểm tra | C6: Gọi khách chủ động trước khi trễ, đưa ETA mới và phương án chuyển tải | D6: Dạ tuyến đang phát sinh kiểm tra và ùn tắc, để giữ đúng giờ giao bên em đề xuất tách 2 điểm nội thành sang xe nhỏ 1.25T. Bên em gửi lại ETA mới ngay sau khi tài xế xác nhận ạ. | E6: Dispatcher + CS | F6: Nếu khách không chấp nhận trễ hoặc hàng vào vùng cấm tải | G6: Customer response, traffic/police report
A7: DYN03 | B7: Chi phí chuyển tải phát sinh | C7: Xin duyệt cấp trên trước khi kích hoạt nếu vượt ngưỡng | D7: Em xin duyệt phương án chuyển tải sang xe 1.25T, chi phí phát sinh dự kiến 1.25 triệu nhưng tránh trễ SLA và bảo vệ doanh thu 5.2 triệu ạ. | E7: Dispatcher | F7: Nếu additional cost > Escalation_Cost_Threshold | G7: Approval screenshot/email
B9: 2 tài xế tự support nhau

Sheet Constraint_Functions
A1: Group | B1: Function_or_Constraint | C1: Mathematical_Form | D1: Operational_Meaning | E1: Used_In_Case
A2: Dynamic Time Window | B2: Cập nhật khung giờ khách thay đổi | C2: TW_i(t+1) = [a_i', b_i'] if customer confirms; otherwise TW_i(t+1)=TW_i(t) | D2: Chỉ cập nhật time window khi có xác nhận khách/kho, tránh hệ thống tự ý thay đổi cam kết dịch vụ. | E2: DYN02
A3: Delay Propagation | B3: Tính ETA mới sau sự cố | C3: ETA_j^new = ETA_i^actual + service_i + travel_ij^updated | D3: Mọi điểm sau sự cố phải được tính lại ETA để biết trễ dây chuyền. | E3: DYN01; DYN03
A4: Soft Time Window | B4: Cho phép trễ có phạt | C4: Late_i = max(0, ETA_i - b_i); Penalty_i = π_i × Late_i | D4: Nếu không thương lượng được, phần trễ chuyển thành chi phí/phạt SLA trong hàm mục tiêu. | E4: All
A5: Candidate Search | B5: Quét xe thay thế trong bán kính | C5: Candidate_k = 1 if 2km ≤ dist(k, incident) ≤ 30km | D5: Khi xe hỏng/bị giữ, hệ thống quét xe rỗng hoặc xe có thể rẽ tuyến trong bán kính 2-30km. | E5: DYN01; DYN03
A6: Capacity Feasibility | B6: Kiểm tra tải và dung tích | C6: AvailableLoad_k ≥ RequiredLoad_r and AvailableVolume_k ≥ RequiredVolume_r | D6: Xe thay thế chỉ hợp lệ nếu đủ tải trọng và dung tích cho phần hàng còn lại. | E6: DYN01; DYN03
A7: Recovery Time Feasibility | B7: Kiểm tra kịp cứu tuyến | C7: ETA_to_incident_k + transferTime + remainingTravel ≤ latestAllowedTime | D7: Xe gần nhưng không kịp thời gian thì không được chọn. | E7: DYN01
A8: Dynamic Re-routing Objective | B8: Tối ưu lại phần còn lại của tuyến | C8: max ΔProfit = Revenue_saved + EmptyCostAvoided - AdditionalCost - LatePenalty - DelayRisk | D8: Không chỉ giảm trễ mà còn bảo vệ lợi nhuận, hạn chế phí rỗng và chi phí phát sinh. | E8: All
A9: Road Restriction | B9: Cấm tải/loại xe không phù hợp | C9: y_ik ≤ comp_ik; comp_ik=0 if vehicle violates road/time restriction | D9: Xe lớn không được vào nội thành trong giờ cấm; cần tách sang xe nhỏ hoặc chuyển tải. | E9: DYN03
A10: Driver Confirmation | B10: Xác nhận tài xế nhận tuyến mới | C10: RouteChange_k is active only if DriverConfirm_k = YES | D10: Không gửi kế hoạch mới xuống khách hàng nếu tài xế chưa xác nhận có thể nhận lệnh. | E10: All
A11: Escalation Rule | B11: Xin duyệt cấp trên | C11: SupervisorApproval = required if AdditionalCost > Threshold or ResidualRisk ∈ {High, Medium-High} | D11: Các phương án phát sinh chi phí lớn/rủi ro cao phải có duyệt trước khi thực hiện. | E11: DYN03
A12: No Cancellation Rule | B12: Không hủy đơn nếu còn phương án khả thi | C12: Cancel_r = 0 if ∃ feasible k or feasible TW negotiation | D12: Hệ thống ưu tiên điều xe, tách điểm, chuyển tải, thương lượng, không hủy đơn. | E12: All
A13: Risk Score | B13: Chấm điểm rủi ro sau xử lý | C13: RiskScore = 0.35×LateRisk + 0.25×CostRisk + 0.2×ComplianceRisk + 0.2×CustomerRisk | D13: Dùng để phân màu Xanh/Vàng/Cam/Đỏ cho dispatcher. | E13: All

Sheet Risk_Register
A1: Case_ID | B1: Risk_ID | C1: Risk_Type | D1: Description | E1: Probability | F1: Severity | G1: Early_Signal | H1: Owner | I1: Mitigation | J1: Escalation
A2: DYN01 | B2: R01 | C2: SLA | D2: Xe hỏng khiến đơn ORD-014 có nguy cơ quá giờ nhập kho cố định | E2: Medium | F2: High | G2: GPS đứng yên >10 phút; tài xế báo lỗi | H2: Dispatcher | I2: Điều xe gần nhất; chuyển tải tại điểm an toàn; gửi ETA mới | J2: Nếu không có xe trong 30km hoặc revised ETA > TW end
A3: DYN01 | B3: R02 | C3: Cost | D3: Chi phí chuyển tải và tài xế phụ làm giảm lợi nhuận tuyến | E3: Medium | F3: Medium | G3: Additional cost > 850k | H3: Ops Supervisor | I3: Chọn xe gần nhất đủ tải, không chọn xe lớn xa hơn nếu không cần | J3: Nếu chi phí > 1 triệu
A4: DYN02 | B4: R03 | C4: Customer | D4: Khách đổi giờ nhưng không xác nhận bằng văn bản/Zalo | E4: Low | F4: Medium | G4: Thông tin chỉ qua cuộc gọi | H4: CS | I4: Yêu cầu xác nhận lại qua Zalo/email, lưu vào Communication Log | J4: Nếu khách từ chối xác nhận
A5: DYN02 | B5: R04 | C5: Waiting | D5: Kho đóng hàng muộn làm xe chờ và trễ điểm sau | E5: Medium | F5: Medium | G5: Warehouse ready time lệch >30 phút | H5: Dispatcher | I5: Đổi thứ tự giao; dùng điểm gần để lấp thời gian chờ | J5: Nếu chờ > thời gian miễn phí
A6: DYN03 | B6: R05 | C6: Compliance | D6: Xe lớn vào nội thành trong giờ cấm tải | E6: Medium | F6: High | G6: ETA rơi vào 16:30-19:30 tại khu hạn chế | H6: Dispatcher | I6: Tách điểm nội thành sang xe 1.25T, xe lớn dừng ngoài vành đai | J6: Luôn xin duyệt nếu phải chuyển tải
A7: DYN03 | B7: R06 | C7: Driver | D7: Tài xế không xác nhận tuyến mới hoặc hết ca | E7: Low | F7: High | G7: Driver confirmation pending >3 phút | H7: Dispatcher | I7: Chuyển sang ứng viên tiếp theo, cập nhật Driver Portal | J7: Nếu 2 ứng viên liên tiếp không xác nhận
A8: DYN03 | B8: R07 | C8: Customer | D8: Khách chỉ chấp nhận trễ tối đa 15 phút | E8: Medium | F8: High | G8: Revised ETA > TW end + 15 phút | H8: CS/Ops | I8: Gọi khách trước, đưa 2 phương án ETA và cam kết xe nhỏ | J8: Nếu khách không đồng ý và có phạt SLA

Sheet Dashboard
A1: DYNAMIC DISPATCH DASHBOARD - 3 IN-DAY EXCEPTION CASES
A3: KPI | B3: Formula/Value | C3: Interpretation
A4: Total dynamic cases | B4: =COUNTA(Dynamic_Cases!A2:A4) -> 3 | C4: Số case động trong ngày
A5: Resolved cases | B5: =COUNTIF(Dynamic_Cases!AB2:AB4,"Resolved") -> 3 | C5: Số case đã có phương án xử lý
A6: On-time after action | B6: =COUNTIF(Dynamic_Cases!V2:V4,"On-time")/COUNTA(Dynamic_Cases!A2:A4) -> 0.66666667 | C6: Tỷ lệ case vẫn giữ được SLA sau xử lý
A7: Average delay before action | B7: =AVERAGE(Dynamic_Cases!T2:T4) -> 48.333333 | C7: Trễ trung bình nếu không xử lý
A8: Average delay after action | B8: =AVERAGE(Dynamic_Cases!U2:U4) -> 55 | C8: Trễ trung bình sau re-route/thương lượng
A9: Total additional cost | B9: =SUM(Dynamic_Cases!X2:X4) -> 2280000 | C9: Tổng chi phí phát sinh để cứu tuyến
A10: Total empty km avoided | B10: =SUM(Dynamic_Cases!Y2:Y4) -> 125 | C10: Km rỗng tránh được nhờ điều phối/ghép tuyến
A11: Total profit protected | B11: =SUM(Dynamic_Cases!AA2:AA4) -> 14895000 | C11: Doanh thu/chi phí được bảo vệ sau xử lý
A14: Case_ID | B14: Event | C14: No Action Delay | D14: After Action Delay | E14: SLA | F14: Selected Decision | G14: Residual Risk
A15: =Dynamic_Cases!A2 -> DYN01 | B15: =Dynamic_Cases!B2 -> Xe hỏng giữa đường - buộc điều xe gần nhất | C15: =Dynamic_Cases!T2 -> 40 | D15: =Dynamic_Cases!U2 -> 0 | E15: =Dynamic_Cases!V2 -> On-time | F15: =Dynamic_Cases!S2 -> Điều xe rỗng gần nhất trong bán kính 2-30km, chuyển tải tại điểm an toàn, gửi lệnh mới cho tài xế và yêu cầu confirm | G15: =Dynamic_Cases!AC2 -> Medium
A16: =Dynamic_Cases!A3 -> DYN02 | B16: =Dynamic_Cases!B3 -> Khách đổi giờ giao + kho đóng hàng muộn | C16: =Dynamic_Cases!T3 -> 35 | D16: =Dynamic_Cases!U3 -> 165 | E16: =Dynamic_Cases!V3 -> Late | F16: =Dynamic_Cases!S3 -> Đổi thứ tự giao: giao ORD-023 trước, giữ xe trên tuyến, cập nhật TW mềm và lưu xác nhận khách hàng | G16: =Dynamic_Cases!AC3 -> Low
A17: =Dynamic_Cases!A4 -> DYN03 | B17: =Dynamic_Cases!B4 -> Tắc đường (phổ biến) + xe bị kiểm tra (optional) | C17: =Dynamic_Cases!T4 -> 70 | D17: =Dynamic_Cases!U4 -> 0 | E17: =Dynamic_Cases!V4 -> On-time | F17: =Dynamic_Cases!S4 -> Tách 2 điểm nội thành sang xe 1.25T gần nhất, xe lớn dừng tại điểm trung chuyển ngoài vành đai, cập nhật ETA cho khách | G17: =Dynamic_Cases!AC4 -> Medium-High
